Workbook
Name MEV_List: #REF!
Name OverrideList: #REF!

Sheet Home 

Sheet Input Data 
B6: Exposure and Rating Wise client date for PD calculation | R6: Frequency Distribution | U6: Check on rows | V6: =IF(COUNTA(B9:B58)=SUM(S9:S20),"Ok","Error") -> Ok
A8: SL.No | B8: Client Name | C8: Product Type | D8: Industry Type | E8: Rating Agency | F8: Drawn Balance (₹ Cr) | G8: Undrawn Commitment (₹ Cr) | H8: Total Exposure (₹ Cr) | I8: Accrued Interest (₹ Cr) | J8: CCF Applied (%) | K8: Borrower Rating | L8: Final EAD | M8: Borrower Rating (aligned) | N8: SICR(Y/N)* | O8: Stage | R8: Rating | S8: Frequency | T8: Stage 1 | U8: Stage 2 | V8: Stage 3
A9: 1 | B9: National Thermal Power Corporation | C9: Lease Financing | D9: Power | E9: CRISIL | F9: 125.06 | G9: 125 | H9: 250 | I9: 2 | J9: 1 | K9: AAA | L9: =F9+(G9*J9)+I9 -> 252.06 | M9: AAA | N9: N | O9: =IF(N9="N","Stage 1","Stage 2") -> Stage 1 | R9: AAA | S9: =COUNTIF($M$9:$M$50,R9) -> 4 | T9: =SUMIFS($L$9:$L$22,$M$9:$M$22,$R9,$O$9:$O$22,$T$8) -> 16859.79 | U9: =SUMIFS($L$9:$L$22,$M$9:$M$22,$R9,$O$9:$O$22,$U$8) -> 0 | V9: =SUMIFS($L$9:$L$22,$M$9:$M$22,$R9,$O$9:$O$22,$V$8) -> 0
A10: 2 | B10: National Thermal Power Corporation Renewable Energy Limited (PPA WITH INDIAN RAILWAY) | C10: Term Loan | D10: Power | E10: India Rating | F10: 3100 | G10: 1900 | H10: 0 | I10: 0 | J10: 0.5 | K10: IND AAA | L10: =F10+(G10*J10)+I10 -> 4050 | M10: AAA | N10: N | O10: =IF(N10="N","Stage 1","Stage 2") -> Stage 1 | R10: AA+ | S10: =COUNTIF($M$9:$M$50,R10) -> 1 | T10: =SUMIFS($L$9:$L$22,$M$9:$M$22,$R10,$O$9:$O$22,$T$8) -> 1103.85 | U10: =SUMIFS($L$9:$L$22,$M$9:$M$22,$R10,$O$9:$O$22,$U$8) -> 0 | V10: =SUMIFS($L$9:$L$22,$M$9:$M$22,$R10,$O$9:$O$22,$V$8) -> 0
A11: 3 | B11: National Thermal Power Corporation (SUPPLY TO INDIAN RAILWAY) | C11: Term Loan | D11: Power | E11: CRISIL | F11: 0 | G11: 5000 | H11: 0 | I11: 0 | J11: 0.5 | K11: AAA | L11: =F11+(G11*J11)+I11 -> 2500 | M11: AAA | N11: N | O11: =IF(N11="N","Stage 1","Stage 2") -> Stage 1 | R11: AA | S11: =COUNTIF($M$9:$M$50,R11) -> 1 | T11: =SUMIFS($L$9:$L$22,$M$9:$M$22,$R11,$O$9:$O$22,$T$8) -> 12103.75 | U11: =SUMIFS($L$9:$L$22,$M$9:$M$22,$R11,$O$9:$O$22,$U$8) -> 0 | V11: =SUMIFS($L$9:$L$22,$M$9:$M$22,$R11,$O$9:$O$22,$V$8) -> 0
A12: 4 | B12: Angul Sukinda Railway Line | C12: Term Loan | D12: Railways | E12: India Rating | F12: 2472.2 | G12: 0 | H12: 2472 | I12: 18.21 | J12: 0 | K12: IND BB+ | L12: =F12+(G12*J12)+I12 -> 2490.41 | M12: BB+ | N12: N | O12: =IF(N12="N","Stage 1","Stage 2") -> Stage 1 | R12: AA- | S12: =COUNTIF($M$9:$M$50,R12) -> 0 | T12: =SUMIFS($L$9:$L$22,$M$9:$M$22,$R12,$O$9:$O$22,$T$8) -> 0 | U12: =SUMIFS($L$9:$L$22,$M$9:$M$22,$R12,$O$9:$O$22,$U$8) -> 0 | V12: =SUMIFS($L$9:$L$22,$M$9:$M$22,$R12,$O$9:$O$22,$V$8) -> 0
A13: 5 | B13: Surat Integrated Transportation Development Corporation Limited (RLDA) | C13: Term Loan | D13: Railways | E13: Unrated | F13: 0 | G13: 200 | H13: 0 | I13: 0 | J13: 1 | K13: Unrated | L13: =F13+(G13*J13)+I13 -> 200 | M13: Unrated | N13: N | O13: =IF(N13="N","Stage 1","Stage 2") -> Stage 1 | R13: A+ | S13: =COUNTIF($M$9:$M$50,R13) -> 1 | T13: =SUMIFS($L$9:$L$22,$M$9:$M$22,$R13,$O$9:$O$22,$T$8) -> 2964.5 | U13: =SUMIFS($L$9:$L$22,$M$9:$M$22,$R13,$O$9:$O$22,$U$8) -> 0 | V13: =SUMIFS($L$9:$L$22,$M$9:$M$22,$R13,$O$9:$O$22,$V$8) -> 0
A14: 6 | B14: Bhartiya Rail Corporation Limited | C14: Term Loan | D14: Power | E14: ICRA | F14: 1096.96 | G14: 0 | H14: 1096.96 | I14: 6.89 | J14: 0 | K14: AA+ | L14: =F14+(G14*J14)+I14 -> 1103.85 | M14: AA+ | N14: N | O14: =IF(N14="N","Stage 1","Stage 2") -> Stage 1 | R14: A | S14: =COUNTIF($M$9:$M$50,R14) -> 1 | T14: =SUMIFS($L$9:$L$22,$M$9:$M$22,$R14,$O$9:$O$22,$T$8) -> 6320.7575 | U14: =SUMIFS($L$9:$L$22,$M$9:$M$22,$R14,$O$9:$O$22,$U$8) -> 0 | V14: =SUMIFS($L$9:$L$22,$M$9:$M$22,$R14,$O$9:$O$22,$V$8) -> 0
A15: 7 | B15: Chhattisgarh State Power Generation Ltd. | C15: Term Loan | D15: Power | E15: India Rating | F15: 1.51 | G15: 12638.49 | H15: 12640 | I15: 0.002459 | J15: 0.5 | K15: IND A | L15: =F15+(G15*J15)+I15 -> 6320.7575 | M15: A | N15: N | O15: =IF(N15="N","Stage 1","Stage 2") -> Stage 1 | R15: A- | S15: =COUNTIF($M$9:$M$50,R15) -> 3 | T15: =SUMIFS($L$9:$L$22,$M$9:$M$22,$R15,$O$9:$O$22,$T$8) -> 12522.26 | U15: =SUMIFS($L$9:$L$22,$M$9:$M$22,$R15,$O$9:$O$22,$U$8) -> 0 | V15: =SUMIFS($L$9:$L$22,$M$9:$M$22,$R15,$O$9:$O$22,$V$8) -> 0
A16: 8 | B16: Talcher Fertilizer Limited | C16: Term Loan | D16: Fertilizers | E16: ICRA | F16: 1259.92 | G16: 2740.08 | H16: 4000 | I16: 9.79 | J16: 0.5 | K16: BBB+ | L16: =F16+(G16*J16)+I16 -> 2639.75 | M16: BBB+ | N16: N | O16: =IF(N16="N","Stage 1","Stage 2") -> Stage 1 | R16: BBB+ | S16: =COUNTIF($M$9:$M$50,R16) -> 1 | T16: =SUMIFS($L$9:$L$22,$M$9:$M$22,$R16,$O$9:$O$22,$T$8) -> 2639.75 | U16: =SUMIFS($L$9:$L$22,$M$9:$M$22,$R16,$O$9:$O$22,$U$8) -> 0 | V16: =SUMIFS($L$9:$L$22,$M$9:$M$22,$R16,$O$9:$O$22,$V$8) -> 0
A17: 9 | B17: Patratu Vidyut Utpadan Nigam Limited | C17: Term Loan | D17: Power | E17: ICRA | F17: 0 | G17: 3389 | H17: 3389 | I17: 0 | J17: =+J16 -> 0.5 | K17: A- | L17: =F17+(G17*J17)+I17 -> 1694.5 | M17: A- | N17: N | O17: =IF(N17="N","Stage 1","Stage 2") -> Stage 1 | R17: BBB | S17: =COUNTIF($M$9:$M$50,R17) -> 0 | T17: =SUMIFS($L$9:$L$22,$M$9:$M$22,$R17,$O$9:$O$22,$T$8) -> 0 | U17: =SUMIFS($L$9:$L$22,$M$9:$M$22,$R17,$O$9:$O$22,$U$8) -> 0 | V17: =SUMIFS($L$9:$L$22,$M$9:$M$22,$R17,$O$9:$O$22,$V$8) -> 0
A18: 10 | B18: Haryana Power Generation Corporation Limited | C18: Term Loan | D18: Power | E18: India Rating | F18: 0 | G18: 5929 | H18: 5929 | I18: 0 | J18: 0.5 | K18: Ind A+ | L18: =F18+(G18*J18)+I18 -> 2964.5 | M18: A+ | N18: N | O18: =IF(N18="N","Stage 1","Stage 2") -> Stage 1 | R18: BBB- | S18: =COUNTIF($M$9:$M$50,R18) -> 0 | T18: =SUMIFS($L$9:$L$22,$M$9:$M$22,$R18,$O$9:$O$22,$T$8) -> 0 | U18: =SUMIFS($L$9:$L$22,$M$9:$M$22,$R18,$O$9:$O$22,$U$8) -> 0 | V18: =SUMIFS($L$9:$L$22,$M$9:$M$22,$R18,$O$9:$O$22,$V$8) -> 0
A19: 11 | B19: Maharashtra State Power Generation Corporation Limited | C19: Term Loan | D19: Power | E19: Acuite Rating | F19: 1017.96 | G19: 9542.04 | H19: =F19+G19 -> 10560 | I19: 6.87 | J19: 0.5 | K19: A- | L19: =F19+(G19*J19)+I19 -> 5795.85 | M19: A- | N19: N | O19: =IF(N19="N","Stage 1","Stage 2") -> Stage 1 | R19: BB+ | S19: =COUNTIF($M$9:$M$50,R19) -> 1 | T19: =SUMIFS($L$9:$L$22,$M$9:$M$22,$R19,$O$9:$O$22,$T$8) -> 2490.41 | U19: =SUMIFS($L$9:$L$22,$M$9:$M$22,$R19,$O$9:$O$22,$U$8) -> 0 | V19: =SUMIFS($L$9:$L$22,$M$9:$M$22,$R19,$O$9:$O$22,$V$8) -> 0
A20: 12 | B20: Dedicated Freight Corridor Corporation of India Limited | C20: Term Loan | D20: Railways | E20: CRISIL | F20: 9821 | G20: 179 | H20: =F20+G20 -> 10000 | I20: 200.93 | J20: 0.2 | K20: AAA | L20: =F20+(G20*J20)+I20 -> 10057.73 | M20: AAA | N20: N | O20: =IF(N20="N","Stage 1","Stage 2") -> Stage 1 | R20: Unrated | S20: =COUNTIF($M$9:$M$50,R20) -> 1 | T20: =SUMIFS($L$9:$L$22,$M$9:$M$22,$R20,$O$9:$O$22,$T$8) -> 200 | U20: =SUMIFS($L$9:$L$22,$M$9:$M$22,$R20,$O$9:$O$22,$U$8) -> 0 | V20: =SUMIFS($L$9:$L$22,$M$9:$M$22,$R20,$O$9:$O$22,$V$8) -> 0
A21: 13 | B21: Maharashtra State Power Generation Corporation Limited | C21: Term Loan | D21: Power | E21: Acuite Rating | F21: 5000 | G21: 0 | H21: =F21+G21 -> 5000 | I21: 31.91 | J21: 0.2 | K21: A- | L21: =F21+(G21*J21)+I21 -> 5031.91 | M21: A- | N21: N | O21: =IF(N21="N","Stage 1","Stage 2") -> Stage 1
A22: 14 | B22: Hindustan Urvarak and Rasayan Limited | C22: Term Loan | D22: Fertilizers | E22: India Rating | F22: 11904.32 | G22: 938 | H22: =F22+G22 -> 12842.32 | I22: 11.83 | J22: 0.2 | K22: IND AA | L22: =F22+(G22*J22)+I22 -> 12103.75 | M22: AA | N22: N | O22: =IF(N22="N","Stage 1","Stage 2") -> Stage 1 | R22: * SICR Assumption: Exposures where the Days Past Due (DPD) exceed 30 days are classified under Stage 2.
A23: =A22+1 -> 15
A24: =A23+1 -> 16
A25: =A24+1 -> 17
A26: =A25+1 -> 18
A27: =A26+1 -> 19
A28: =A27+1 -> 20
A29: =A28+1 -> 21
A30: =A29+1 -> 22
A31: =A30+1 -> 23
A32: =A31+1 -> 24
A33: =A32+1 -> 25
A34: =A33+1 -> 26
... A58: =A57+1 -> 50

Sheet TTC PD
C6: Rating wise TTC PD*: | G6: Screeen shot of Crisil PD Matrix
C7: CRISIL RATING | D7: CRISIL Default TTC PD
C8: ='Input Data '!R9 -> AAA | D8: 0.0003
C9: ='Input Data '!R10 -> AA+ | D9: 0.0029
C10: ='Input Data '!R11 -> AA | D10: 0.0029
C11: ='Input Data '!R12 -> AA- | D11: 0.0029
C12: ='Input Data '!R13 -> A+ | D12: 0.0066
C13: ='Input Data '!R14 -> A | D13: 0.0066
C14: ='Input Data '!R15 -> A- | D14: 0.0066
C15: ='Input Data '!R16 -> BBB+ | D15: 0.0221
C16: ='Input Data '!R17 -> BBB | D16: 0.0221
C17: ='Input Data '!R18 -> BBB- | D17: 0.0221
C18: ='Input Data '!R19 -> BB+ | D18: 0.0992
C19: ='Input Data '!R20 -> Unrated | D19: 0.0992
C21: * Note: PD's to be changed on annual basis | G21: Link For Crisil PD's
G22: https://www.crisil.com/content/dam/crisil/our-analysis/publications/default-study/crisil-ratings-annual-default-and-ratings-transition-study-fy-2025.pdf

Sheet MEV Data
B6: Macroeconomic Variable: Historical and Forecasted Values
B8: Series Title | C8: 2020 | D8: 2021 | E8: 2022 | F8: 2023 | G8: 2024 | H8: 2025 | I8: 2026 | J8: 2027 | K8: 2028 | L8: 2029 | M8: 2030 | N8: 2031 | O8: LTM(Long Term Mean) | P8: SD | Q8: CV
B9: Unemployment Rate | C9: 8.662 | D9: 7.365 | E9: 5.3 | F9: 4.939 | G9: 4.939 | H9: 4.939 | I9: 4.939 | J9: 4.939 | K9: 4.939 | L9: 4.939 | M9: 4.939 | N9: 4.939 | O9: =AVERAGE(C9:I9) -> 5.869 | P9: =_xlfn.STDEV.P(C9:I9) -> 1.4052059 | Q9: =(P9/O9) -> 0.23942851
B10: GDP | C10: -5.778 | D10: 9.69 | E10: 7.609 | F10: 7.21 | G10: 7.099 | H10: 7.618 | I10: 6.478 | J10: 6.529 | K10: 6.5 | L10: 6.52 | M10: 6.503 | N10: 6.514 | O10: =AVERAGE(C10:I10) -> 5.7037143 | P10: =_xlfn.STDEV.P(C10:I10) -> 4.7783751 | Q10: =P10/O10 -> 0.8377655
B11: Inflation | C11: 4.769 | D11: 6.154 | E11: 5.512 | F11: 6.634 | G11: 5.37 | H11: 4.639 | I11: 2.091 | J11: 4.715 | K11: 4 | L11: 4 | M11: 4 | N11: 4 | O11: =AVERAGE(C11:I11) -> 5.0241429 | P11: =_xlfn.STDEV.P(C11:I11) -> 1.3650012 | Q11: =(P11/O11)*100 -> 27.168838
B12: Govt_Revenue | C12: 36044.776 | D12: 48228.993 | E12: 54137.903 | F12: 61815.407 | G12: 68141.219 | H12: 72847.417 | I12: 81625.055 | J12: 90990.196 | K12: 101388.78 | L12: 113003.81 | M12: 125934.9 | N12: 140367.34 | O12: =AVERAGE(C12:I12) -> 60405.824 | P12: =_xlfn.STDEV.P(C12:I12) -> 14382.007 | Q12: =(P12/O12)*100 -> 23.808975
B13: General government gross debt | C13: 90.562 | D13: 85.713 | E13: 84.598 | F13: 85.01 | G13: 84.782 | H13: 84.075 | I13: 83.362 | J13: 82.546 | K13: 81.663 | L13: 80.609 | M13: 79.465 | N13: 77.689 | O13: =AVERAGE(C13:I13) -> 85.443143 | P13: =_xlfn.STDEV.P(C13:I13) -> 2.1979692 | Q13: =(P13/O13)*100 -> 2.5724349

Sheet MEV_Index
B6: Macro Economic Variable (MEV):
A7: A | B7: Variable as per Policy | C7: Variable 1 | D7: Variable 2
B8: Selected MEV | C8: ='MEV Data'!B10 -> GDP | D8: ='MEV Data'!B12 -> Govt_Revenue
B9: Weights | C9: 0.5 | D9: =100%-C9 -> 0.5
A11: B | B11: Variable | C11: =D11-1 -> 2020 | D11: =E11-1 -> 2021 | E11: =F11-1 -> 2022 | F11: =G11-1 -> 2023 | G11: =H11-1 -> 2024 | H11: =I11-1 -> 2025 | I11: 2026 | J11: =I11+1 -> 2027 | K11: =J11+1 -> 2028 | L11: =K11+1 -> 2029 | M11: =L11+1 -> 2030 | N11: =M11+1 -> 2031
B12: =C8 -> GDP | C12: {=_xlfn.XLOOKUP($C$8,'MEV Data'!$B$9:$B$13,'MEV Data'!$C$9:$N$13,"Not Found")} -> -5.778 | D12: 9.69 | E12: 7.609 | F12: 7.21 | G12: 7.099 | H12: 7.618 | I12: 6.478 | J12: 6.529 | K12: 6.5 | L12: 6.52 | M12: 6.503 | N12: 6.514
B13: =D8 -> Govt_Revenue | C13: {=_xlfn.XLOOKUP($D$8,'MEV Data'!$B$9:$B$13,'MEV Data'!$C$9:$N$13,"Not Found")} -> 36044.776 | D13: 48228.993 | E13: 54137.903 | F13: 61815.407 | G13: 68141.219 | H13: 72847.417 | I13: 81625.055 | J13: 90990.196 | K13: 101388.78 | L13: 113003.81 | M13: 125934.9 | N13: 140367.34
A16: C | B16: Scenerio Development
C17: =B12 -> GDP | D17: =B13 -> Govt_Revenue
B18: Long Term Mean | C18: =AVERAGE(C12:I12) -> 5.7037143 | D18: =AVERAGE(C13:I13) -> 60405.824
B19: Standard Deviation | C19: =_xlfn.STDEV.P(C12:I12) -> 4.7783751 | D19: =_xlfn.STDEV.P(C13:I13) -> 14382.007
A21: D | B21: Z_Factor
B22: Variable | C22: =C11 -> 2020 | D22: =C22+1 -> 2021 | E22: =D22+1 -> 2022 | F22: =E22+1 -> 2023 | G22: =F22+1 -> 2024 | H22: =G22+1 -> 2025 | I22: =H22+1 -> 2026 | J22: =I22+1 -> 2027 | K22: =J22+1 -> 2028 | ... N22: =M22+1 -> 2031
B23: =B12 -> GDP | C23: =(C12-$C$18)/$C$19 -> -2.4028491 | D23: =(D12-$C$18)/$C$19 -> 0.83423458 | E23: =(E12-$C$18)/$C$19 -> 0.39873088 | F23: =(F12-$C$18)/$C$19 -> 0.3152297 | G23: =(G12-$C$18)/$C$19 -> 0.29200004 | H23: =(H12-$C$18)/$C$19 -> 0.40061437 | I23: =(I12-$C$18)/$C$19 -> 0.16203954 | J23: =(J12-$C$18)/$C$19 -> 0.17271263 | ... N23: =(N12-$C$18)/$C$19 -> 0.16957349
B24: =B13 -> Govt_Revenue | C24: =(C13-$D$18)/$D$19 -> -1.6938559 | D24: =(D13-$D$18)/$D$19 -> -0.84667118 | E24: =(E13-$D$18)/$D$19 -> -0.43581686 | F24: =(F13-$D$18)/$D$19 -> 0.098010151 | G24: =(G13-$D$18)/$D$19 -> 0.53785223 | H24: =(H13-$D$18)/$D$19 -> 0.8650804 | I24: =(I13-$D$18)/$D$19 -> 1.4754012 | J24: =(J13-$D$18)/$D$19 -> 2.1265718 | ... N24: =(N13-$D$18)/$D$19 -> 5.55983
A26: E | B26: MEV_Index
B27: Variable | C27: =C22 -> 2020 | D27: =C27+1 -> 2021 | E27: =D27+1 -> 2022 | F27: =E27+1 -> 2023 | G27: =F27+1 -> 2024 | H27: =G27+1 -> 2025 | I27: =H27+1 -> 2026 | J27: =I27+1 -> 2027 | K27: =J27+1 -> 2028 | ... N27: =M27+1 -> 2031
B28: Index | C28: =C23*$C$9+C24*$D$9 -> -2.0483525 | D28: =D23*$C$9+D24*$D$9 -> -0.0062183021 | E28: =E23*$C$9+E24*$D$9 -> -0.018542986 | F28: =F23*$C$9+F24*$D$9 -> 0.20661992 | G28: =G23*$C$9+G24*$D$9 -> 0.41492613 | H28: =H23*$C$9+H24*$D$9 -> 0.63284738 | I28: =I23*$C$9+I24*$D$9 -> 0.81872036 | J28: =J23*$C$9+J24*$D$9 -> 1.1496422 | ... N28: =N23*$C$9+N24*$D$9 -> 2.8647018

Sheet MEV Scenario
A7: MEV Scenario
A9: Base
A10: Variable | B10: =MEV_Index!C11 -> 2020 | C10: =MEV_Index!D11 -> 2021 | D10: =MEV_Index!E11 -> 2022 | E10: =MEV_Index!F11 -> 2023 | F10: =MEV_Index!G11 -> 2024 | G10: =MEV_Index!H11 -> 2025 | H10: =MEV_Index!I11 -> 2026 | I10: =MEV_Index!J11 -> 2027 | ... M10: =MEV_Index!N11 -> 2031
A11: MEV_Index | B11: =MEV_Index!C28 -> -2.0483525 | C11: =MEV_Index!D28 -> -0.0062183021 | D11: =MEV_Index!E28 -> -0.018542986 | E11: =MEV_Index!F28 -> 0.20661992 | F11: =MEV_Index!G28 -> 0.41492613 | G11: =MEV_Index!H28 -> 0.63284738 | H11: =MEV_Index!I28 -> 0.81872036 | I11: =MEV_Index!J28 -> 1.1496422 | ... M11: =MEV_Index!N28 -> 2.8647018
A14: Upturn
A15: Variable | B15: =B10 -> 2020 | C15: =C10 -> 2021 | D15: =D10 -> 2022 | E15: =E10 -> 2023 | F15: =F10 -> 2024 | G15: =G10 -> 2025 | H15: =H10 -> 2026 | I15: =I10 -> 2027 | ... M15: =M10 -> 2031
A16: MEV_Index | B16: =IF(B11<0,B11*Admin!$B$14,B11*Admin!$B$15) -> -1.8435173 | C16: =IF(C11<0,C11*Admin!$B$14,C11*Admin!$B$15) -> -0.0055964719 | D16: =IF(D11<0,D11*Admin!$B$14,D11*Admin!$B$15) -> -0.016688688 | E16: =IF(E11<0,E11*Admin!$B$14,E11*Admin!$B$15) -> 0.22728192 | F16: =IF(F11<0,F11*Admin!$B$14,F11*Admin!$B$15) -> 0.45641875 | G16: =IF(G11<0,G11*Admin!$B$14,G11*Admin!$B$15) -> 0.69613212 | H16: =IF(H11<0,H11*Admin!$B$14,H11*Admin!$B$15) -> 0.9005924 | I16: =IF(I11<0,I11*Admin!$B$14,I11*Admin!$B$15) -> 1.2646064 | ... M16: =IF(M11<0,M11*Admin!$B$14,M11*Admin!$B$15) -> 3.1511719
A19: Downturn
A20: Variable | B20: =B15 -> 2020 | C20: =C15 -> 2021 | D20: =D15 -> 2022 | E20: =E15 -> 2023 | F20: =F15 -> 2024 | G20: =G15 -> 2025 | H20: =H15 -> 2026 | I20: =I15 -> 2027 | ... M20: =M15 -> 2031
A21: MEV_Index | B21: =IF(B11<0,B11*Admin!$B$15,B11*Admin!$B$14) -> -2.2531878 | C21: =IF(C11<0,C11*Admin!$B$15,C11*Admin!$B$14) -> -0.0068401323 | D21: =IF(D11<0,D11*Admin!$B$15,D11*Admin!$B$14) -> -0.020397285 | E21: =IF(E11<0,E11*Admin!$B$15,E11*Admin!$B$14) -> 0.18595793 | F21: =IF(F11<0,F11*Admin!$B$15,F11*Admin!$B$14) -> 0.37343352 | G21: =IF(G11<0,G11*Admin!$B$15,G11*Admin!$B$14) -> 0.56956265 | H21: =IF(H11<0,H11*Admin!$B$15,H11*Admin!$B$14) -> 0.73684832 | I21: =IF(I11<0,I11*Admin!$B$15,I11*Admin!$B$14) -> 1.034678 | ... M21: =IF(M11<0,M11*Admin!$B$15,M11*Admin!$B$14) -> 2.5782316

Sheet Vasicek
B6: Forecast Probability of Default
B8: Base | E8: 2026 | F8: =E8+1 -> 2027 | G8: =F8+1 -> 2028 | H8: =G8+1 -> 2029 | I8: =H8+1 -> 2030 | J8: =I8+1 -> 2031
B9: Grades | C9: TTC | D9: Asset Correlation | E9: ='MEV Scenario'!H11 -> 0.81872036 | F9: ='MEV Scenario'!I11 -> 1.1496422 | G9: ='MEV Scenario'!J11 -> 1.5081213 | H9: ='MEV Scenario'!K11 -> 1.9140184 | I9: ='MEV Scenario'!L11 -> 2.3617974 | J9: ='MEV Scenario'!M11 -> 2.8647018
B10: ='TTC PD'!C8 -> AAA | C10: ='TTC PD'!D8 -> 0.0003 | D10: =(0.12*(1-EXP(-50*C10))/(1-EXP(-50)))+0.24*(1-(1-EXP(-50*C10))/(1-EXP(-50))) -> 0.23821343 | E10: =IFERROR( IF( NORMSDIST((NORMSINV($C10)-SQRT($D10)*E$9)/SQRT(1-$D10))<0.03%, 0.03%, NORMSDIST((NORMSINV($C10)-SQRT($D10)*E$9)/SQRT(1-$D10)) ), 0.03% ) -> 0.0003 | F10: =IFERROR( IF( NORMSDIST((NORMSINV($C10)-SQRT($D10)*F$9)/SQRT(1-$D10))<0.03%, 0.03%, NORMSDIST((NORMSINV($C10)-SQRT($D10)*F$9)/SQRT(1-$D10)) ), 0.03% ) -> 0.0003 | G10: =IFERROR( IF( NORMSDIST((NORMSINV($C10)-SQRT($D10)*G$9)/SQRT(1-$D10))<0.03%, 0.03%, NORMSDIST((NORMSINV($C10)-SQRT($D10)*G$9)/SQRT(1-$D10)) ), 0.03% ) -> 0.0003 | H10: =IFERROR( IF( NORMSDIST((NORMSINV($C10)-SQRT($D10)*H$9)/SQRT(1-$D10))<0.03%, 0.03%, NORMSDIST((NORMSINV($C10)-SQRT($D10)*H$9)/SQRT(1-$D10)) ), 0.03% ) -> 0.0003 | I10: =IFERROR( IF( NORMSDIST((NORMSINV($C10)-SQRT($D10)*I$9)/SQRT(1-$D10))<0.03%, 0.03%, NORMSDIST((NORMSINV($C10)-SQRT($D10)*I$9)/SQRT(1-$D10)) ), 0.03% ) -> 0.0003 | J10: =IFERROR( IF( NORMSDIST((NORMSINV($C10)-SQRT($D10)*J$9)/SQRT(1-$D10))<0.03%, 0.03%, NORMSDIST((NORMSINV($C10)-SQRT($D10)*J$9)/SQRT(1-$D10)) ), 0.03% ) -> 0.0003
B11: ='TTC PD'!C9 -> AA+ | C11: ='TTC PD'!D9 -> 0.0029 | D11: =(0.12*(1-EXP(-50*C11))/(1-EXP(-50)))+0.24*(1-(1-EXP(-50*C11))/(1-EXP(-50))) -> 0.22380268 | E11: =IFERROR( IF( NORMSDIST((NORMSINV($C11)-SQRT($D11)*E$9)/SQRT(1-$D11))<0.03%, 0.03%, NORMSDIST((NORMSINV($C11)-SQRT($D11)*E$9)/SQRT(1-$D11)) ), 0.03% ) -> 0.0003 | F11: =IFERROR( IF( NORMSDIST((NORMSINV($C11)-SQRT($D11)*F$9)/SQRT(1-$D11))<0.03%, 0.03%, NORMSDIST((NORMSINV($C11)-SQRT($D11)*F$9)/SQRT(1-$D11)) ), 0.03% ) -> 0.0003 | G11: =IFERROR( IF( NORMSDIST((NORMSINV($C11)-SQRT($D11)*G$9)/SQRT(1-$D11))<0.03%, 0.03%, NORMSDIST((NORMSINV($C11)-SQRT($D11)*G$9)/SQRT(1-$D11)) ), 0.03% ) -> 0.0003 | H11: =IFERROR( IF( NORMSDIST((NORMSINV($C11)-SQRT($D11)*H$9)/SQRT(1-$D11))<0.03%, 0.03%, NORMSDIST((NORMSINV($C11)-SQRT($D11)*H$9)/SQRT(1-$D11)) ), 0.03% ) -> 0.0003 | I11: =IFERROR( IF( NORMSDIST((NORMSINV($C11)-SQRT($D11)*I$9)/SQRT(1-$D11))<0.03%, 0.03%, NORMSDIST((NORMSINV($C11)-SQRT($D11)*I$9)/SQRT(1-$D11)) ), 0.03% ) -> 0.0003 | J11: =IFERROR( IF( NORMSDIST((NORMSINV($C11)-SQRT($D11)*J$9)/SQRT(1-$D11))<0.03%, 0.03%, NORMSDIST((NORMSINV($C11)-SQRT($D11)*J$9)/SQRT(1-$D11)) ), 0.03% ) -> 0.0003
B12: ='TTC PD'!C10 -> AA | C12: ='TTC PD'!D10 -> 0.0029 | D12: =(0.12*(1-EXP(-50*C12))/(1-EXP(-50)))+0.24*(1-(1-EXP(-50*C12))/(1-EXP(-50))) -> 0.22380268 | E12: =IFERROR( IF( NORMSDIST((NORMSINV($C12)-SQRT($D12)*E$9)/SQRT(1-$D12))<0.03%, 0.03%, NORMSDIST((NORMSINV($C12)-SQRT($D12)*E$9)/SQRT(1-$D12)) ), 0.03% ) -> 0.0003 | F12: =IFERROR( IF( NORMSDIST((NORMSINV($C12)-SQRT($D12)*F$9)/SQRT(1-$D12))<0.03%, 0.03%, NORMSDIST((NORMSINV($C12)-SQRT($D12)*F$9)/SQRT(1-$D12)) ), 0.03% ) -> 0.0003 | G12: =IFERROR( IF( NORMSDIST((NORMSINV($C12)-SQRT($D12)*G$9)/SQRT(1-$D12))<0.03%, 0.03%, NORMSDIST((NORMSINV($C12)-SQRT($D12)*G$9)/SQRT(1-$D12)) ), 0.03% ) -> 0.0003 | H12: =IFERROR( IF( NORMSDIST((NORMSINV($C12)-SQRT($D12)*H$9)/SQRT(1-$D12))<0.03%, 0.03%, NORMSDIST((NORMSINV($C12)-SQRT($D12)*H$9)/SQRT(1-$D12)) ), 0.03% ) -> 0.0003 | I12: =IFERROR( IF( NORMSDIST((NORMSINV($C12)-SQRT($D12)*I$9)/SQRT(1-$D12))<0.03%, 0.03%, NORMSDIST((NORMSINV($C12)-SQRT($D12)*I$9)/SQRT(1-$D12)) ), 0.03% ) -> 0.0003 | J12: =IFERROR( IF( NORMSDIST((NORMSINV($C12)-SQRT($D12)*J$9)/SQRT(1-$D12))<0.03%, 0.03%, NORMSDIST((NORMSINV($C12)-SQRT($D12)*J$9)/SQRT(1-$D12)) ), 0.03% ) -> 0.0003
B13: ='TTC PD'!C11 -> AA- | C13: ='TTC PD'!D11 -> 0.0029 | D13: =(0.12*(1-EXP(-50*C13))/(1-EXP(-50)))+0.24*(1-(1-EXP(-50*C13))/(1-EXP(-50))) -> 0.22380268 | E13: =IFERROR( IF( NORMSDIST((NORMSINV($C13)-SQRT($D13)*E$9)/SQRT(1-$D13))<0.03%, 0.03%, NORMSDIST((NORMSINV($C13)-SQRT($D13)*E$9)/SQRT(1-$D13)) ), 0.03% ) -> 0.0003 | F13: =IFERROR( IF( NORMSDIST((NORMSINV($C13)-SQRT($D13)*F$9)/SQRT(1-$D13))<0.03%, 0.03%, NORMSDIST((NORMSINV($C13)-SQRT($D13)*F$9)/SQRT(1-$D13)) ), 0.03% ) -> 0.0003 | G13: =IFERROR( IF( NORMSDIST((NORMSINV($C13)-SQRT($D13)*G$9)/SQRT(1-$D13))<0.03%, 0.03%, NORMSDIST((NORMSINV($C13)-SQRT($D13)*G$9)/SQRT(1-$D13)) ), 0.03% ) -> 0.0003 | H13: =IFERROR( IF( NORMSDIST((NORMSINV($C13)-SQRT($D13)*H$9)/SQRT(1-$D13))<0.03%, 0.03%, NORMSDIST((NORMSINV($C13)-SQRT($D13)*H$9)/SQRT(1-$D13)) ), 0.03% ) -> 0.0003 | I13: =IFERROR( IF( NORMSDIST((NORMSINV($C13)-SQRT($D13)*I$9)/SQRT(1-$D13))<0.03%, 0.03%, NORMSDIST((NORMSINV($C13)-SQRT($D13)*I$9)/SQRT(1-$D13)) ), 0.03% ) -> 0.0003 | J13: =IFERROR( IF( NORMSDIST((NORMSINV($C13)-SQRT($D13)*J$9)/SQRT(1-$D13))<0.03%, 0.03%, NORMSDIST((NORMSINV($C13)-SQRT($D13)*J$9)/SQRT(1-$D13)) ), 0.03% ) -> 0.0003
B14: ='TTC PD'!C12 -> A+ | C14: ='TTC PD'!D12 -> 0.0066 | D14: =(0.12*(1-EXP(-50*C14))/(1-EXP(-50)))+0.24*(1-(1-EXP(-50*C14))/(1-EXP(-50))) -> 0.20627085 | E14: =IFERROR( IF( NORMSDIST((NORMSINV($C14)-SQRT($D14)*E$9)/SQRT(1-$D14))<0.03%, 0.03%, NORMSDIST((NORMSINV($C14)-SQRT($D14)*E$9)/SQRT(1-$D14)) ), 0.03% ) -> 0.00068917818 | F14: =IFERROR( IF( NORMSDIST((NORMSINV($C14)-SQRT($D14)*F$9)/SQRT(1-$D14))<0.03%, 0.03%, NORMSDIST((NORMSINV($C14)-SQRT($D14)*F$9)/SQRT(1-$D14)) ), 0.03% ) -> 0.00037879399 | G14: =IFERROR( IF( NORMSDIST((NORMSINV($C14)-SQRT($D14)*G$9)/SQRT(1-$D14))<0.03%, 0.03%, NORMSDIST((NORMSINV($C14)-SQRT($D14)*G$9)/SQRT(1-$D14)) ), 0.03% ) -> 0.0003 | H14: =IFERROR( IF( NORMSDIST((NORMSINV($C14)-SQRT($D14)*H$9)/SQRT(1-$D14))<0.03%, 0.03%, NORMSDIST((NORMSINV($C14)-SQRT($D14)*H$9)/SQRT(1-$D14)) ), 0.03% ) -> 0.0003 | I14: =IFERROR( IF( NORMSDIST((NORMSINV($C14)-SQRT($D14)*I$9)/SQRT(1-$D14))<0.03%, 0.03%, NORMSDIST((NORMSINV($C14)-SQRT($D14)*I$9)/SQRT(1-$D14)) ), 0.03% ) -> 0.0003 | J14: =IFERROR( IF( NORMSDIST((NORMSINV($C14)-SQRT($D14)*J$9)/SQRT(1-$D14))<0.03%, 0.03%, NORMSDIST((NORMSINV($C14)-SQRT($D14)*J$9)/SQRT(1-$D14)) ), 0.03% ) -> 0.0003
B15: ='TTC PD'!C13 -> A | C15: ='TTC PD'!D13 -> 0.0066 | D15: =(0.12*(1-EXP(-50*C15))/(1-EXP(-50)))+0.24*(1-(1-EXP(-50*C15))/(1-EXP(-50))) -> 0.20627085 | E15: =IFERROR( IF( NORMSDIST((NORMSINV($C15)-SQRT($D15)*E$9)/SQRT(1-$D15))<0.03%, 0.03%, NORMSDIST((NORMSINV($C15)-SQRT($D15)*E$9)/SQRT(1-$D15)) ), 0.03% ) -> 0.00068917818 | F15: =IFERROR( IF( NORMSDIST((NORMSINV($C15)-SQRT($D15)*F$9)/SQRT(1-$D15))<0.03%, 0.03%, NORMSDIST((NORMSINV($C15)-SQRT($D15)*F$9)/SQRT(1-$D15)) ), 0.03% ) -> 0.00037879399 | G15: =IFERROR( IF( NORMSDIST((NORMSINV($C15)-SQRT($D15)*G$9)/SQRT(1-$D15))<0.03%, 0.03%, NORMSDIST((NORMSINV($C15)-SQRT($D15)*G$9)/SQRT(1-$D15)) ), 0.03% ) -> 0.0003 | H15: =IFERROR( IF( NORMSDIST((NORMSINV($C15)-SQRT($D15)*H$9)/SQRT(1-$D15))<0.03%, 0.03%, NORMSDIST((NORMSINV($C15)-SQRT($D15)*H$9)/SQRT(1-$D15)) ), 0.03% ) -> 0.0003 | I15: =IFERROR( IF( NORMSDIST((NORMSINV($C15)-SQRT($D15)*I$9)/SQRT(1-$D15))<0.03%, 0.03%, NORMSDIST((NORMSINV($C15)-SQRT($D15)*I$9)/SQRT(1-$D15)) ), 0.03% ) -> 0.0003 | J15: =IFERROR( IF( NORMSDIST((NORMSINV($C15)-SQRT($D15)*J$9)/SQRT(1-$D15))<0.03%, 0.03%, NORMSDIST((NORMSINV($C15)-SQRT($D15)*J$9)/SQRT(1-$D15)) ), 0.03% ) -> 0.0003
B16: ='TTC PD'!C14 -> A- | C16: ='TTC PD'!D14 -> 0.0066 | D16: =(0.12*(1-EXP(-50*C16))/(1-EXP(-50)))+0.24*(1-(1-EXP(-50*C16))/(1-EXP(-50))) -> 0.20627085 | E16: =IFERROR( IF( NORMSDIST((NORMSINV($C16)-SQRT($D16)*E$9)/SQRT(1-$D16))<0.03%, 0.03%, NORMSDIST((NORMSINV($C16)-SQRT($D16)*E$9)/SQRT(1-$D16)) ), 0.03% ) -> 0.00068917818 | F16: =IFERROR( IF( NORMSDIST((NORMSINV($C16)-SQRT($D16)*F$9)/SQRT(1-$D16))<0.03%, 0.03%, NORMSDIST((NORMSINV($C16)-SQRT($D16)*F$9)/SQRT(1-$D16)) ), 0.03% ) -> 0.00037879399 | G16: =IFERROR( IF( NORMSDIST((NORMSINV($C16)-SQRT($D16)*G$9)/SQRT(1-$D16))<0.03%, 0.03%, NORMSDIST((NORMSINV($C16)-SQRT($D16)*G$9)/SQRT(1-$D16)) ), 0.03% ) -> 0.0003 | H16: =IFERROR( IF( NORMSDIST((NORMSINV($C16)-SQRT($D16)*H$9)/SQRT(1-$D16))<0.03%, 0.03%, NORMSDIST((NORMSINV($C16)-SQRT($D16)*H$9)/SQRT(1-$D16)) ), 0.03% ) -> 0.0003 | I16: =IFERROR( IF( NORMSDIST((NORMSINV($C16)-SQRT($D16)*I$9)/SQRT(1-$D16))<0.03%, 0.03%, NORMSDIST((NORMSINV($C16)-SQRT($D16)*I$9)/SQRT(1-$D16)) ), 0.03% ) -> 0.0003 | J16: =IFERROR( IF( NORMSDIST((NORMSINV($C16)-SQRT($D16)*J$9)/SQRT(1-$D16))<0.03%, 0.03%, NORMSDIST((NORMSINV($C16)-SQRT($D16)*J$9)/SQRT(1-$D16)) ), 0.03% ) -> 0.0003
B17: ='TTC PD'!C15 -> BBB+ | C17: ='TTC PD'!D15 -> 0.0221 | D17: =(0.12*(1-EXP(-50*C17))/(1-EXP(-50)))+0.24*(1-(1-EXP(-50*C17))/(1-EXP(-50))) -> 0.15974531 | E17: =IFERROR( IF( NORMSDIST((NORMSINV($C17)-SQRT($D17)*E$9)/SQRT(1-$D17))<0.03%, 0.03%, NORMSDIST((NORMSINV($C17)-SQRT($D17)*E$9)/SQRT(1-$D17)) ), 0.03% ) -> 0.005353392 | F17: =IFERROR( IF( NORMSDIST((NORMSINV($C17)-SQRT($D17)*F$9)/SQRT(1-$D17))<0.03%, 0.03%, NORMSDIST((NORMSINV($C17)-SQRT($D17)*F$9)/SQRT(1-$D17)) ), 0.03% ) -> 0.003504513 | G17: =IFERROR( IF( NORMSDIST((NORMSINV($C17)-SQRT($D17)*G$9)/SQRT(1-$D17))<0.03%, 0.03%, NORMSDIST((NORMSINV($C17)-SQRT($D17)*G$9)/SQRT(1-$D17)) ), 0.03% ) -> 0.0021673403 | H17: =IFERROR( IF( NORMSDIST((NORMSINV($C17)-SQRT($D17)*H$9)/SQRT(1-$D17))<0.03%, 0.03%, NORMSDIST((NORMSINV($C17)-SQRT($D17)*H$9)/SQRT(1-$D17)) ), 0.03% ) -> 0.0012239835 | I17: =IFERROR( IF( NORMSDIST((NORMSINV($C17)-SQRT($D17)*I$9)/SQRT(1-$D17))<0.03%, 0.03%, NORMSDIST((NORMSINV($C17)-SQRT($D17)*I$9)/SQRT(1-$D17)) ), 0.03% ) -> 0.00062999172 | J17: =IFERROR( IF( NORMSDIST((NORMSINV($C17)-SQRT($D17)*J$9)/SQRT(1-$D17))<0.03%, 0.03%, NORMSDIST((NORMSINV($C17)-SQRT($D17)*J$9)/SQRT(1-$D17)) ), 0.03% ) -> 0.0003
B18: ='TTC PD'!C16 -> BBB | C18: ='TTC PD'!D16 -> 0.0221 | D18: =(0.12*(1-EXP(-50*C18))/(1-EXP(-50)))+0.24*(1-(1-EXP(-50*C18))/(1-EXP(-50))) -> 0.15974531 | E18: =IFERROR( IF( NORMSDIST((NORMSINV($C18)-SQRT($D18)*E$9)/SQRT(1-$D18))<0.03%, 0.03%, NORMSDIST((NORMSINV($C18)-SQRT($D18)*E$9)/SQRT(1-$D18)) ), 0.03% ) -> 0.005353392 | F18: =IFERROR( IF( NORMSDIST((NORMSINV($C18)-SQRT($D18)*F$9)/SQRT(1-$D18))<0.03%, 0.03%, NORMSDIST((NORMSINV($C18)-SQRT($D18)*F$9)/SQRT(1-$D18)) ), 0.03% ) -> 0.003504513 | G18: =IFERROR( IF( NORMSDIST((NORMSINV($C18)-SQRT($D18)*G$9)/SQRT(1-$D18))<0.03%, 0.03%, NORMSDIST((NORMSINV($C18)-SQRT($D18)*G$9)/SQRT(1-$D18)) ), 0.03% ) -> 0.0021673403 | H18: =IFERROR( IF( NORMSDIST((NORMSINV($C18)-SQRT($D18)*H$9)/SQRT(1-$D18))<0.03%, 0.03%, NORMSDIST((NORMSINV($C18)-SQRT($D18)*H$9)/SQRT(1-$D18)) ), 0.03% ) -> 0.0012239835 | I18: =IFERROR( IF( NORMSDIST((NORMSINV($C18)-SQRT($D18)*I$9)/SQRT(1-$D18))<0.03%, 0.03%, NORMSDIST((NORMSINV($C18)-SQRT($D18)*I$9)/SQRT(1-$D18)) ), 0.03% ) -> 0.00062999172 | J18: =IFERROR( IF( NORMSDIST((NORMSINV($C18)-SQRT($D18)*J$9)/SQRT(1-$D18))<0.03%, 0.03%, NORMSDIST((NORMSINV($C18)-SQRT($D18)*J$9)/SQRT(1-$D18)) ), 0.03% ) -> 0.0003
B19: ='TTC PD'!C17 -> BBB- | C19: ='TTC PD'!D17 -> 0.0221 | D19: =(0.12*(1-EXP(-50*C19))/(1-EXP(-50)))+0.24*(1-(1-EXP(-50*C19))/(1-EXP(-50))) -> 0.15974531 | E19: =IFERROR( IF( NORMSDIST((NORMSINV($C19)-SQRT($D19)*E$9)/SQRT(1-$D19))<0.03%, 0.03%, NORMSDIST((NORMSINV($C19)-SQRT($D19)*E$9)/SQRT(1-$D19)) ), 0.03% ) -> 0.005353392 | F19: =IFERROR( IF( NORMSDIST((NORMSINV($C19)-SQRT($D19)*F$9)/SQRT(1-$D19))<0.03%, 0.03%, NORMSDIST((NORMSINV($C19)-SQRT($D19)*F$9)/SQRT(1-$D19)) ), 0.03% ) -> 0.003504513 | G19: =IFERROR( IF( NORMSDIST((NORMSINV($C19)-SQRT($D19)*G$9)/SQRT(1-$D19))<0.03%, 0.03%, NORMSDIST((NORMSINV($C19)-SQRT($D19)*G$9)/SQRT(1-$D19)) ), 0.03% ) -> 0.0021673403 | H19: =IFERROR( IF( NORMSDIST((NORMSINV($C19)-SQRT($D19)*H$9)/SQRT(1-$D19))<0.03%, 0.03%, NORMSDIST((NORMSINV($C19)-SQRT($D19)*H$9)/SQRT(1-$D19)) ), 0.03% ) -> 0.0012239835 | I19: =IFERROR( IF( NORMSDIST((NORMSINV($C19)-SQRT($D19)*I$9)/SQRT(1-$D19))<0.03%, 0.03%, NORMSDIST((NORMSINV($C19)-SQRT($D19)*I$9)/SQRT(1-$D19)) ), 0.03% ) -> 0.00062999172 | J19: =IFERROR( IF( NORMSDIST((NORMSINV($C19)-SQRT($D19)*J$9)/SQRT(1-$D19))<0.03%, 0.03%, NORMSDIST((NORMSINV($C19)-SQRT($D19)*J$9)/SQRT(1-$D19)) ), 0.03% ) -> 0.0003
B20: ='TTC PD'!C18 -> BB+ | C20: ='TTC PD'!D18 -> 0.0992 | D20: =(0.12*(1-EXP(-50*C20))/(1-EXP(-50)))+0.24*(1-(1-EXP(-50*C20))/(1-EXP(-50))) -> 0.12084155 | E20: =IFERROR( IF( NORMSDIST((NORMSINV($C20)-SQRT($D20)*E$9)/SQRT(1-$D20))<0.03%, 0.03%, NORMSDIST((NORMSINV($C20)-SQRT($D20)*E$9)/SQRT(1-$D20)) ), 0.03% ) -> 0.046947093 | F20: =IFERROR( IF( NORMSDIST((NORMSINV($C20)-SQRT($D20)*F$9)/SQRT(1-$D20))<0.03%, 0.03%, NORMSDIST((NORMSINV($C20)-SQRT($D20)*F$9)/SQRT(1-$D20)) ), 0.03% ) -> 0.036097097 | G20: =IFERROR( IF( NORMSDIST((NORMSINV($C20)-SQRT($D20)*G$9)/SQRT(1-$D20))<0.03%, 0.03%, NORMSDIST((NORMSINV($C20)-SQRT($D20)*G$9)/SQRT(1-$D20)) ), 0.03% ) -> 0.026754164 | H20: =IFERROR( IF( NORMSDIST((NORMSINV($C20)-SQRT($D20)*H$9)/SQRT(1-$D20))<0.03%, 0.03%, NORMSDIST((NORMSINV($C20)-SQRT($D20)*H$9)/SQRT(1-$D20)) ), 0.03% ) -> 0.018704154 | I20: =IFERROR( IF( NORMSDIST((NORMSINV($C20)-SQRT($D20)*I$9)/SQRT(1-$D20))<0.03%, 0.03%, NORMSDIST((NORMSINV($C20)-SQRT($D20)*I$9)/SQRT(1-$D20)) ), 0.03% ) -> 0.012310709 | J20: =IFERROR( IF( NORMSDIST((NORMSINV($C20)-SQRT($D20)*J$9)/SQRT(1-$D20))<0.03%, 0.03%, NORMSDIST((NORMSINV($C20)-SQRT($D20)*J$9)/SQRT(1-$D20)) ), 0.03% ) -> 0.0074718577
B21: ='TTC PD'!C19 -> Unrated | C21: ='TTC PD'!D19 -> 0.0992 | D21: =(0.12*(1-EXP(-50*C21))/(1-EXP(-50)))+0.24*(1-(1-EXP(-50*C21))/(1-EXP(-50))) -> 0.12084155 | E21: =IFERROR( IF( NORMSDIST((NORMSINV($C21)-SQRT($D21)*E$9)/SQRT(1-$D21))<0.03%, 0.03%, NORMSDIST((NORMSINV($C21)-SQRT($D21)*E$9)/SQRT(1-$D21)) ), 0.03% ) -> 0.046947093 | F21: =IFERROR( IF( NORMSDIST((NORMSINV($C21)-SQRT($D21)*F$9)/SQRT(1-$D21))<0.03%, 0.03%, NORMSDIST((NORMSINV($C21)-SQRT($D21)*F$9)/SQRT(1-$D21)) ), 0.03% ) -> 0.036097097 | G21: =IFERROR( IF( NORMSDIST((NORMSINV($C21)-SQRT($D21)*G$9)/SQRT(1-$D21))<0.03%, 0.03%, NORMSDIST((NORMSINV($C21)-SQRT($D21)*G$9)/SQRT(1-$D21)) ), 0.03% ) -> 0.026754164 | H21: =IFERROR( IF( NORMSDIST((NORMSINV($C21)-SQRT($D21)*H$9)/SQRT(1-$D21))<0.03%, 0.03%, NORMSDIST((NORMSINV($C21)-SQRT($D21)*H$9)/SQRT(1-$D21)) ), 0.03% ) -> 0.018704154 | I21: =IFERROR( IF( NORMSDIST((NORMSINV($C21)-SQRT($D21)*I$9)/SQRT(1-$D21))<0.03%, 0.03%, NORMSDIST((NORMSINV($C21)-SQRT($D21)*I$9)/SQRT(1-$D21)) ), 0.03% ) -> 0.012310709 | J21: =IFERROR( IF( NORMSDIST((NORMSINV($C21)-SQRT($D21)*J$9)/SQRT(1-$D21))<0.03%, 0.03%, NORMSDIST((NORMSINV($C21)-SQRT($D21)*J$9)/SQRT(1-$D21)) ), 0.03% ) -> 0.0074718577
B23: Upturn | E23: 2026 | F23: =E23+1 -> 2027 | G23: =F23+1 -> 2028 | H23: =G23+1 -> 2029 | I23: =H23+1 -> 2030 | J23: =I23+1 -> 2031
B24: Grades | C24: TTC | D24: Asset Correlation | E24: ='MEV Scenario'!H16 -> 0.9005924 | F24: ='MEV Scenario'!I16 -> 1.2646064 | G24: ='MEV Scenario'!J16 -> 1.6589334 | H24: ='MEV Scenario'!K16 -> 2.1054203 | I24: ='MEV Scenario'!L16 -> 2.5979772 | J24: ='MEV Scenario'!M16 -> 3.1511719
B25: =B10 -> AAA | C25: =C10 -> 0.0003 | D25: =(0.12*(1-EXP(-50*C25))/(1-EXP(-50)))+0.24*(1-(1-EXP(-50*C25))/(1-EXP(-50))) -> 0.23821343 | E25: =IFERROR( IF( NORMSDIST((NORMSINV($C25)-SQRT($D25)*E$24)/SQRT(1-$D25))<0.03%, 0.03%, NORMSDIST((NORMSINV($C25)-SQRT($D25)*E$24)/SQRT(1-$D25)) ), 0.03% ) -> 0.0003 | F25: =IFERROR( IF( NORMSDIST((NORMSINV($C25)-SQRT($D25)*F$24)/SQRT(1-$D25))<0.03%, 0.03%, NORMSDIST((NORMSINV($C25)-SQRT($D25)*F$24)/SQRT(1-$D25)) ), 0.03% ) -> 0.0003 | G25: =IFERROR( IF( NORMSDIST((NORMSINV($C25)-SQRT($D25)*G$24)/SQRT(1-$D25))<0.03%, 0.03%, NORMSDIST((NORMSINV($C25)-SQRT($D25)*G$24)/SQRT(1-$D25)) ), 0.03% ) -> 0.0003 | H25: =IFERROR( IF( NORMSDIST((NORMSINV($C25)-SQRT($D25)*H$24)/SQRT(1-$D25))<0.03%, 0.03%, NORMSDIST((NORMSINV($C25)-SQRT($D25)*H$24)/SQRT(1-$D25)) ), 0.03% ) -> 0.0003 | I25: =IFERROR( IF( NORMSDIST((NORMSINV($C25)-SQRT($D25)*I$24)/SQRT(1-$D25))<0.03%, 0.03%, NORMSDIST((NORMSINV($C25)-SQRT($D25)*I$24)/SQRT(1-$D25)) ), 0.03% ) -> 0.0003 | J25: =IFERROR( IF( NORMSDIST((NORMSINV($C25)-SQRT($D25)*J$24)/SQRT(1-$D25))<0.03%, 0.03%, NORMSDIST((NORMSINV($C25)-SQRT($D25)*J$24)/SQRT(1-$D25)) ), 0.03% ) -> 0.0003
B26: =B11 -> AA+ | C26: =C11 -> 0.0029 | D26: =(0.12*(1-EXP(-50*C26))/(1-EXP(-50)))+0.24*(1-(1-EXP(-50*C26))/(1-EXP(-50))) -> 0.22380268 | E26: =IFERROR( IF( NORMSDIST((NORMSINV($C26)-SQRT($D26)*E$24)/SQRT(1-$D26))<0.03%, 0.03%, NORMSDIST((NORMSINV($C26)-SQRT($D26)*E$24)/SQRT(1-$D26)) ), 0.03% ) -> 0.0003 | F26: =IFERROR( IF( NORMSDIST((NORMSINV($C26)-SQRT($D26)*F$24)/SQRT(1-$D26))<0.03%, 0.03%, NORMSDIST((NORMSINV($C26)-SQRT($D26)*F$24)/SQRT(1-$D26)) ), 0.03% ) -> 0.0003 | G26: =IFERROR( IF( NORMSDIST((NORMSINV($C26)-SQRT($D26)*G$24)/SQRT(1-$D26))<0.03%, 0.03%, NORMSDIST((NORMSINV($C26)-SQRT($D26)*G$24)/SQRT(1-$D26)) ), 0.03% ) -> 0.0003 | H26: =IFERROR( IF( NORMSDIST((NORMSINV($C26)-SQRT($D26)*H$24)/SQRT(1-$D26))<0.03%, 0.03%, NORMSDIST((NORMSINV($C26)-SQRT($D26)*H$24)/SQRT(1-$D26)) ), 0.03% ) -> 0.0003 | I26: =IFERROR( IF( NORMSDIST((NORMSINV($C26)-SQRT($D26)*I$24)/SQRT(1-$D26))<0.03%, 0.03%, NORMSDIST((NORMSINV($C26)-SQRT($D26)*I$24)/SQRT(1-$D26)) ), 0.03% ) -> 0.0003 | J26: =IFERROR( IF( NORMSDIST((NORMSINV($C26)-SQRT($D26)*J$24)/SQRT(1-$D26))<0.03%, 0.03%, NORMSDIST((NORMSINV($C26)-SQRT($D26)*J$24)/SQRT(1-$D26)) ), 0.03% ) -> 0.0003
B27: =B12 -> AA | C27: =C12 -> 0.0029 | D27: =(0.12*(1-EXP(-50*C27))/(1-EXP(-50)))+0.24*(1-(1-EXP(-50*C27))/(1-EXP(-50))) -> 0.22380268 | E27: =IFERROR( IF( NORMSDIST((NORMSINV($C27)-SQRT($D27)*E$24)/SQRT(1-$D27))<0.03%, 0.03%, NORMSDIST((NORMSINV($C27)-SQRT($D27)*E$24)/SQRT(1-$D27)) ), 0.03% ) -> 0.0003 | F27: =IFERROR( IF( NORMSDIST((NORMSINV($C27)-SQRT($D27)*F$24)/SQRT(1-$D27))<0.03%, 0.03%, NORMSDIST((NORMSINV($C27)-SQRT($D27)*F$24)/SQRT(1-$D27)) ), 0.03% ) -> 0.0003 | G27: =IFERROR( IF( NORMSDIST((NORMSINV($C27)-SQRT($D27)*G$24)/SQRT(1-$D27))<0.03%, 0.03%, NORMSDIST((NORMSINV($C27)-SQRT($D27)*G$24)/SQRT(1-$D27)) ), 0.03% ) -> 0.0003 | H27: =IFERROR( IF( NORMSDIST((NORMSINV($C27)-SQRT($D27)*H$24)/SQRT(1-$D27))<0.03%, 0.03%, NORMSDIST((NORMSINV($C27)-SQRT($D27)*H$24)/SQRT(1-$D27)) ), 0.03% ) -> 0.0003 | I27: =IFERROR( IF( NORMSDIST((NORMSINV($C27)-SQRT($D27)*I$24)/SQRT(1-$D27))<0.03%, 0.03%, NORMSDIST((NORMSINV($C27)-SQRT($D27)*I$24)/SQRT(1-$D27)) ), 0.03% ) -> 0.0003 | J27: =IFERROR( IF( NORMSDIST((NORMSINV($C27)-SQRT($D27)*J$24)/SQRT(1-$D27))<0.03%, 0.03%, NORMSDIST((NORMSINV($C27)-SQRT($D27)*J$24)/SQRT(1-$D27)) ), 0.03% ) -> 0.0003
B28: =B13 -> AA- | C28: =C13 -> 0.0029 | D28: =(0.12*(1-EXP(-50*C28))/(1-EXP(-50)))+0.24*(1-(1-EXP(-50*C28))/(1-EXP(-50))) -> 0.22380268 | E28: =IFERROR( IF( NORMSDIST((NORMSINV($C28)-SQRT($D28)*E$24)/SQRT(1-$D28))<0.03%, 0.03%, NORMSDIST((NORMSINV($C28)-SQRT($D28)*E$24)/SQRT(1-$D28)) ), 0.03% ) -> 0.0003 | F28: =IFERROR( IF( NORMSDIST((NORMSINV($C28)-SQRT($D28)*F$24)/SQRT(1-$D28))<0.03%, 0.03%, NORMSDIST((NORMSINV($C28)-SQRT($D28)*F$24)/SQRT(1-$D28)) ), 0.03% ) -> 0.0003 | G28: =IFERROR( IF( NORMSDIST((NORMSINV($C28)-SQRT($D28)*G$24)/SQRT(1-$D28))<0.03%, 0.03%, NORMSDIST((NORMSINV($C28)-SQRT($D28)*G$24)/SQRT(1-$D28)) ), 0.03% ) -> 0.0003 | H28: =IFERROR( IF( NORMSDIST((NORMSINV($C28)-SQRT($D28)*H$24)/SQRT(1-$D28))<0.03%, 0.03%, NORMSDIST((NORMSINV($C28)-SQRT($D28)*H$24)/SQRT(1-$D28)) ), 0.03% ) -> 0.0003 | I28: =IFERROR( IF( NORMSDIST((NORMSINV($C28)-SQRT($D28)*I$24)/SQRT(1-$D28))<0.03%, 0.03%, NORMSDIST((NORMSINV($C28)-SQRT($D28)*I$24)/SQRT(1-$D28)) ), 0.03% ) -> 0.0003 | J28: =IFERROR( IF( NORMSDIST((NORMSINV($C28)-SQRT($D28)*J$24)/SQRT(1-$D28))<0.03%, 0.03%, NORMSDIST((NORMSINV($C28)-SQRT($D28)*J$24)/SQRT(1-$D28)) ), 0.03% ) -> 0.0003
B29: =B14 -> A+ | C29: =C14 -> 0.0066 | D29: =(0.12*(1-EXP(-50*C29))/(1-EXP(-50)))+0.24*(1-(1-EXP(-50*C29))/(1-EXP(-50))) -> 0.20627085 | E29: =IFERROR( IF( NORMSDIST((NORMSINV($C29)-SQRT($D29)*E$24)/SQRT(1-$D29))<0.03%, 0.03%, NORMSDIST((NORMSINV($C29)-SQRT($D29)*E$24)/SQRT(1-$D29)) ), 0.03% ) -> 0.00059580224 | F29: =IFERROR( IF( NORMSDIST((NORMSINV($C29)-SQRT($D29)*F$24)/SQRT(1-$D29))<0.03%, 0.03%, NORMSDIST((NORMSINV($C29)-SQRT($D29)*F$24)/SQRT(1-$D29)) ), 0.03% ) -> 0.00030576408 | G29: =IFERROR( IF( NORMSDIST((NORMSINV($C29)-SQRT($D29)*G$24)/SQRT(1-$D29))<0.03%, 0.03%, NORMSDIST((NORMSINV($C29)-SQRT($D29)*G$24)/SQRT(1-$D29)) ), 0.03% ) -> 0.0003 | H29: =IFERROR( IF( NORMSDIST((NORMSINV($C29)-SQRT($D29)*H$24)/SQRT(1-$D29))<0.03%, 0.03%, NORMSDIST((NORMSINV($C29)-SQRT($D29)*H$24)/SQRT(1-$D29)) ), 0.03% ) -> 0.0003 | I29: =IFERROR( IF( NORMSDIST((NORMSINV($C29)-SQRT($D29)*I$24)/SQRT(1-$D29))<0.03%, 0.03%, NORMSDIST((NORMSINV($C29)-SQRT($D29)*I$24)/SQRT(1-$D29)) ), 0.03% ) -> 0.0003 | J29: =IFERROR( IF( NORMSDIST((NORMSINV($C29)-SQRT($D29)*J$24)/SQRT(1-$D29))<0.03%, 0.03%, NORMSDIST((NORMSINV($C29)-SQRT($D29)*J$24)/SQRT(1-$D29)) ), 0.03% ) -> 0.0003
B30: =B15 -> A | C30: =C15 -> 0.0066 | D30: =(0.12*(1-EXP(-50*C30))/(1-EXP(-50)))+0.24*(1-(1-EXP(-50*C30))/(1-EXP(-50))) -> 0.20627085 | E30: =IFERROR( IF( NORMSDIST((NORMSINV($C30)-SQRT($D30)*E$24)/SQRT(1-$D30))<0.03%, 0.03%, NORMSDIST((NORMSINV($C30)-SQRT($D30)*E$24)/SQRT(1-$D30)) ), 0.03% ) -> 0.00059580224 | F30: =IFERROR( IF( NORMSDIST((NORMSINV($C30)-SQRT($D30)*F$24)/SQRT(1-$D30))<0.03%, 0.03%, NORMSDIST((NORMSINV($C30)-SQRT($D30)*F$24)/SQRT(1-$D30)) ), 0.03% ) -> 0.00030576408 | G30: =IFERROR( IF( NORMSDIST((NORMSINV($C30)-SQRT($D30)*G$24)/SQRT(1-$D30))<0.03%, 0.03%, NORMSDIST((NORMSINV($C30)-SQRT($D30)*G$24)/SQRT(1-$D30)) ), 0.03% ) -> 0.0003 | H30: =IFERROR( IF( NORMSDIST((NORMSINV($C30)-SQRT($D30)*H$24)/SQRT(1-$D30))<0.03%, 0.03%, NORMSDIST((NORMSINV($C30)-SQRT($D30)*H$24)/SQRT(1-$D30)) ), 0.03% ) -> 0.0003 | I30: =IFERROR( IF( NORMSDIST((NORMSINV($C30)-SQRT($D30)*I$24)/SQRT(1-$D30))<0.03%, 0.03%, NORMSDIST((NORMSINV($C30)-SQRT($D30)*I$24)/SQRT(1-$D30)) ), 0.03% ) -> 0.0003 | J30: =IFERROR( IF( NORMSDIST((NORMSINV($C30)-SQRT($D30)*J$24)/SQRT(1-$D30))<0.03%, 0.03%, NORMSDIST((NORMSINV($C30)-SQRT($D30)*J$24)/SQRT(1-$D30)) ), 0.03% ) -> 0.0003
B31: =B16 -> A- | C31: =C16 -> 0.0066 | D31: =(0.12*(1-EXP(-50*C31))/(1-EXP(-50)))+0.24*(1-(1-EXP(-50*C31))/(1-EXP(-50))) -> 0.20627085 | E31: =IFERROR( IF( NORMSDIST((NORMSINV($C31)-SQRT($D31)*E$24)/SQRT(1-$D31))<0.03%, 0.03%, NORMSDIST((NORMSINV($C31)-SQRT($D31)*E$24)/SQRT(1-$D31)) ), 0.03% ) -> 0.00059580224 | F31: =IFERROR( IF( NORMSDIST((NORMSINV($C31)-SQRT($D31)*F$24)/SQRT(1-$D31))<0.03%, 0.03%, NORMSDIST((NORMSINV($C31)-SQRT($D31)*F$24)/SQRT(1-$D31)) ), 0.03% ) -> 0.00030576408 | G31: =IFERROR( IF( NORMSDIST((NORMSINV($C31)-SQRT($D31)*G$24)/SQRT(1-$D31))<0.03%, 0.03%, NORMSDIST((NORMSINV($C31)-SQRT($D31)*G$24)/SQRT(1-$D31)) ), 0.03% ) -> 0.0003 | H31: =IFERROR( IF( NORMSDIST((NORMSINV($C31)-SQRT($D31)*H$24)/SQRT(1-$D31))<0.03%, 0.03%, NORMSDIST((NORMSINV($C31)-SQRT($D31)*H$24)/SQRT(1-$D31)) ), 0.03% ) -> 0.0003 | I31: =IFERROR( IF( NORMSDIST((NORMSINV($C31)-SQRT($D31)*I$24)/SQRT(1-$D31))<0.03%, 0.03%, NORMSDIST((NORMSINV($C31)-SQRT($D31)*I$24)/SQRT(1-$D31)) ), 0.03% ) -> 0.0003 | J31: =IFERROR( IF( NORMSDIST((NORMSINV($C31)-SQRT($D31)*J$24)/SQRT(1-$D31))<0.03%, 0.03%, NORMSDIST((NORMSINV($C31)-SQRT($D31)*J$24)/SQRT(1-$D31)) ), 0.03% ) -> 0.0003
B32: =B17 -> BBB+ | C32: =C17 -> 0.0221 | D32: =(0.12*(1-EXP(-50*C32))/(1-EXP(-50)))+0.24*(1-(1-EXP(-50*C32))/(1-EXP(-50))) -> 0.15974531 | E32: =IFERROR( IF( NORMSDIST((NORMSINV($C32)-SQRT($D32)*E$24)/SQRT(1-$D32))<0.03%, 0.03%, NORMSDIST((NORMSINV($C32)-SQRT($D32)*E$24)/SQRT(1-$D32)) ), 0.03% ) -> 0.0048292177 | F32: =IFERROR( IF( NORMSDIST((NORMSINV($C32)-SQRT($D32)*F$24)/SQRT(1-$D32))<0.03%, 0.03%, NORMSDIST((NORMSINV($C32)-SQRT($D32)*F$24)/SQRT(1-$D32)) ), 0.03% ) -> 0.0030113581 | G32: =IFERROR( IF( NORMSDIST((NORMSINV($C32)-SQRT($D32)*G$24)/SQRT(1-$D32))<0.03%, 0.03%, NORMSDIST((NORMSINV($C32)-SQRT($D32)*G$24)/SQRT(1-$D32)) ), 0.03% ) -> 0.0017587271 | H32: =IFERROR( IF( NORMSDIST((NORMSINV($C32)-SQRT($D32)*H$24)/SQRT(1-$D32))<0.03%, 0.03%, NORMSDIST((NORMSINV($C32)-SQRT($D32)*H$24)/SQRT(1-$D32)) ), 0.03% ) -> 0.0009254922 | I32: =IFERROR( IF( NORMSDIST((NORMSINV($C32)-SQRT($D32)*I$24)/SQRT(1-$D32))<0.03%, 0.03%, NORMSDIST((NORMSINV($C32)-SQRT($D32)*I$24)/SQRT(1-$D32)) ), 0.03% ) -> 0.00043748296 | J32: =IFERROR( IF( NORMSDIST((NORMSINV($C32)-SQRT($D32)*J$24)/SQRT(1-$D32))<0.03%, 0.03%, NORMSDIST((NORMSINV($C32)-SQRT($D32)*J$24)/SQRT(1-$D32)) ), 0.03% ) -> 0.0003
B33: =B18 -> BBB | C33: =C18 -> 0.0221 | D33: =(0.12*(1-EXP(-50*C33))/(1-EXP(-50)))+0.24*(1-(1-EXP(-50*C33))/(1-EXP(-50))) -> 0.15974531 | E33: =IFERROR( IF( NORMSDIST((NORMSINV($C33)-SQRT($D33)*E$24)/SQRT(1-$D33))<0.03%, 0.03%, NORMSDIST((NORMSINV($C33)-SQRT($D33)*E$24)/SQRT(1-$D33)) ), 0.03% ) -> 0.0048292177 | F33: =IFERROR( IF( NORMSDIST((NORMSINV($C33)-SQRT($D33)*F$24)/SQRT(1-$D33))<0.03%, 0.03%, NORMSDIST((NORMSINV($C33)-SQRT($D33)*F$24)/SQRT(1-$D33)) ), 0.03% ) -> 0.0030113581 | G33: =IFERROR( IF( NORMSDIST((NORMSINV($C33)-SQRT($D33)*G$24)/SQRT(1-$D33))<0.03%, 0.03%, NORMSDIST((NORMSINV($C33)-SQRT($D33)*G$24)/SQRT(1-$D33)) ), 0.03% ) -> 0.0017587271 | H33: =IFERROR( IF( NORMSDIST((NORMSINV($C33)-SQRT($D33)*H$24)/SQRT(1-$D33))<0.03%, 0.03%, NORMSDIST((NORMSINV($C33)-SQRT($D33)*H$24)/SQRT(1-$D33)) ), 0.03% ) -> 0.0009254922 | I33: =IFERROR( IF( NORMSDIST((NORMSINV($C33)-SQRT($D33)*I$24)/SQRT(1-$D33))<0.03%, 0.03%, NORMSDIST((NORMSINV($C33)-SQRT($D33)*I$24)/SQRT(1-$D33)) ), 0.03% ) -> 0.00043748296 | J33: =IFERROR( IF( NORMSDIST((NORMSINV($C33)-SQRT($D33)*J$24)/SQRT(1-$D33))<0.03%, 0.03%, NORMSDIST((NORMSINV($C33)-SQRT($D33)*J$24)/SQRT(1-$D33)) ), 0.03% ) -> 0.0003
B34: =B19 -> BBB- | C34: =C19 -> 0.0221 | D34: =(0.12*(1-EXP(-50*C34))/(1-EXP(-50)))+0.24*(1-(1-EXP(-50*C34))/(1-EXP(-50))) -> 0.15974531 | E34: =IFERROR( IF( NORMSDIST((NORMSINV($C34)-SQRT($D34)*E$24)/SQRT(1-$D34))<0.03%, 0.03%, NORMSDIST((NORMSINV($C34)-SQRT($D34)*E$24)/SQRT(1-$D34)) ), 0.03% ) -> 0.0048292177 | F34: =IFERROR( IF( NORMSDIST((NORMSINV($C34)-SQRT($D34)*F$24)/SQRT(1-$D34))<0.03%, 0.03%, NORMSDIST((NORMSINV($C34)-SQRT($D34)*F$24)/SQRT(1-$D34)) ), 0.03% ) -> 0.0030113581 | G34: =IFERROR( IF( NORMSDIST((NORMSINV($C34)-SQRT($D34)*G$24)/SQRT(1-$D34))<0.03%, 0.03%, NORMSDIST((NORMSINV($C34)-SQRT($D34)*G$24)/SQRT(1-$D34)) ), 0.03% ) -> 0.0017587271 | H34: =IFERROR( IF( NORMSDIST((NORMSINV($C34)-SQRT($D34)*H$24)/SQRT(1-$D34))<0.03%, 0.03%, NORMSDIST((NORMSINV($C34)-SQRT($D34)*H$24)/SQRT(1-$D34)) ), 0.03% ) -> 0.0009254922 | I34: =IFERROR( IF( NORMSDIST((NORMSINV($C34)-SQRT($D34)*I$24)/SQRT(1-$D34))<0.03%, 0.03%, NORMSDIST((NORMSINV($C34)-SQRT($D34)*I$24)/SQRT(1-$D34)) ), 0.03% ) -> 0.00043748296 | J34: =IFERROR( IF( NORMSDIST((NORMSINV($C34)-SQRT($D34)*J$24)/SQRT(1-$D34))<0.03%, 0.03%, NORMSDIST((NORMSINV($C34)-SQRT($D34)*J$24)/SQRT(1-$D34)) ), 0.03% ) -> 0.0003
B35: =B20 -> BB+ | C35: =C20 -> 0.0992 | D35: =(0.12*(1-EXP(-50*C35))/(1-EXP(-50)))+0.24*(1-(1-EXP(-50*C35))/(1-EXP(-50))) -> 0.12084155 | E35: =IFERROR( IF( NORMSDIST((NORMSINV($C35)-SQRT($D35)*E$24)/SQRT(1-$D35))<0.03%, 0.03%, NORMSDIST((NORMSINV($C35)-SQRT($D35)*E$24)/SQRT(1-$D35)) ), 0.03% ) -> 0.044045227 | F35: =IFERROR( IF( NORMSDIST((NORMSINV($C35)-SQRT($D35)*F$24)/SQRT(1-$D35))<0.03%, 0.03%, NORMSDIST((NORMSINV($C35)-SQRT($D35)*F$24)/SQRT(1-$D35)) ), 0.03% ) -> 0.032846413 | G35: =IFERROR( IF( NORMSDIST((NORMSINV($C35)-SQRT($D35)*G$24)/SQRT(1-$D35))<0.03%, 0.03%, NORMSDIST((NORMSINV($C35)-SQRT($D35)*G$24)/SQRT(1-$D35)) ), 0.03% ) -> 0.023477361 | H35: =IFERROR( IF( NORMSDIST((NORMSINV($C35)-SQRT($D35)*H$24)/SQRT(1-$D35))<0.03%, 0.03%, NORMSDIST((NORMSINV($C35)-SQRT($D35)*H$24)/SQRT(1-$D35)) ), 0.03% ) -> 0.015689193 | I35: =IFERROR( IF( NORMSDIST((NORMSINV($C35)-SQRT($D35)*I$24)/SQRT(1-$D35))<0.03%, 0.03%, NORMSDIST((NORMSINV($C35)-SQRT($D35)*I$24)/SQRT(1-$D35)) ), 0.03% ) -> 0.0097755354 | J35: =IFERROR( IF( NORMSDIST((NORMSINV($C35)-SQRT($D35)*J$24)/SQRT(1-$D35))<0.03%, 0.03%, NORMSDIST((NORMSINV($C35)-SQRT($D35)*J$24)/SQRT(1-$D35)) ), 0.03% ) -> 0.0055434565
B36: =B21 -> Unrated | C36: =C21 -> 0.0992 | D36: =(0.12*(1-EXP(-50*C36))/(1-EXP(-50)))+0.24*(1-(1-EXP(-50*C36))/(1-EXP(-50))) -> 0.12084155 | E36: =IFERROR( IF( NORMSDIST((NORMSINV($C36)-SQRT($D36)*E$24)/SQRT(1-$D36))<0.03%, 0.03%, NORMSDIST((NORMSINV($C36)-SQRT($D36)*E$24)/SQRT(1-$D36)) ), 0.03% ) -> 0.044045227 | F36: =IFERROR( IF( NORMSDIST((NORMSINV($C36)-SQRT($D36)*F$24)/SQRT(1-$D36))<0.03%, 0.03%, NORMSDIST((NORMSINV($C36)-SQRT($D36)*F$24)/SQRT(1-$D36)) ), 0.03% ) -> 0.032846413 | G36: =IFERROR( IF( NORMSDIST((NORMSINV($C36)-SQRT($D36)*G$24)/SQRT(1-$D36))<0.03%, 0.03%, NORMSDIST((NORMSINV($C36)-SQRT($D36)*G$24)/SQRT(1-$D36)) ), 0.03% ) -> 0.023477361 | H36: =IFERROR( IF( NORMSDIST((NORMSINV($C36)-SQRT($D36)*H$24)/SQRT(1-$D36))<0.03%, 0.03%, NORMSDIST((NORMSINV($C36)-SQRT($D36)*H$24)/SQRT(1-$D36)) ), 0.03% ) -> 0.015689193 | I36: =IFERROR( IF( NORMSDIST((NORMSINV($C36)-SQRT($D36)*I$24)/SQRT(1-$D36))<0.03%, 0.03%, NORMSDIST((NORMSINV($C36)-SQRT($D36)*I$24)/SQRT(1-$D36)) ), 0.03% ) -> 0.0097755354 | J36: =IFERROR( IF( NORMSDIST((NORMSINV($C36)-SQRT($D36)*J$24)/SQRT(1-$D36))<0.03%, 0.03%, NORMSDIST((NORMSINV($C36)-SQRT($D36)*J$24)/SQRT(1-$D36)) ), 0.03% ) -> 0.0055434565
B39: Downturn | E39: 2026 | F39: =E39+1 -> 2027 | G39: =F39+1 -> 2028 | H39: =G39+1 -> 2029 | I39: =H39+1 -> 2030 | J39: =I39+1 -> 2031
B40: Grades | C40: TTC | D40: Asset Correlation | E40: ='MEV Scenario'!H21 -> 0.73684832 | F40: ='MEV Scenario'!I21 -> 1.034678 | G40: ='MEV Scenario'!J21 -> 1.3573091 | H40: ='MEV Scenario'!K21 -> 1.7226166 | I40: ='MEV Scenario'!L21 -> 2.1256177 | J40: ='MEV Scenario'!M21 -> 2.5782316
B41: =B25 -> AAA | C41: =C10 -> 0.0003 | D41: =(0.12*(1-EXP(-50*C41))/(1-EXP(-50)))+0.24*(1-(1-EXP(-50*C41))/(1-EXP(-50))) -> 0.23821343 | E41: =IFERROR( IF( NORMSDIST((NORMSINV($C41)-SQRT($D41)*E$40)/SQRT(1-$D41))<0.03%, 0.03%, NORMSDIST((NORMSINV($C41)-SQRT($D41)*E$40)/SQRT(1-$D41)) ), 0.03% ) -> 0.0003 | F41: =IFERROR( IF( NORMSDIST((NORMSINV($C41)-SQRT($D41)*F$40)/SQRT(1-$D41))<0.03%, 0.03%, NORMSDIST((NORMSINV($C41)-SQRT($D41)*F$40)/SQRT(1-$D41)) ), 0.03% ) -> 0.0003 | G41: =IFERROR( IF( NORMSDIST((NORMSINV($C41)-SQRT($D41)*G$40)/SQRT(1-$D41))<0.03%, 0.03%, NORMSDIST((NORMSINV($C41)-SQRT($D41)*G$40)/SQRT(1-$D41)) ), 0.03% ) -> 0.0003 | H41: =IFERROR( IF( NORMSDIST((NORMSINV($C41)-SQRT($D41)*H$40)/SQRT(1-$D41))<0.03%, 0.03%, NORMSDIST((NORMSINV($C41)-SQRT($D41)*H$40)/SQRT(1-$D41)) ), 0.03% ) -> 0.0003 | I41: =IFERROR( IF( NORMSDIST((NORMSINV($C41)-SQRT($D41)*I$40)/SQRT(1-$D41))<0.03%, 0.03%, NORMSDIST((NORMSINV($C41)-SQRT($D41)*I$40)/SQRT(1-$D41)) ), 0.03% ) -> 0.0003 | J41: =IFERROR( IF( NORMSDIST((NORMSINV($C41)-SQRT($D41)*J$40)/SQRT(1-$D41))<0.03%, 0.03%, NORMSDIST((NORMSINV($C41)-SQRT($D41)*J$40)/SQRT(1-$D41)) ), 0.03% ) -> 0.0003
B42: =B26 -> AA+ | C42: =C11 -> 0.0029 | D42: =(0.12*(1-EXP(-50*C42))/(1-EXP(-50)))+0.24*(1-(1-EXP(-50*C42))/(1-EXP(-50))) -> 0.22380268 | E42: =IFERROR( IF( NORMSDIST((NORMSINV($C42)-SQRT($D42)*E$40)/SQRT(1-$D42))<0.03%, 0.03%, NORMSDIST((NORMSINV($C42)-SQRT($D42)*E$40)/SQRT(1-$D42)) ), 0.03% ) -> 0.0003 | F42: =IFERROR( IF( NORMSDIST((NORMSINV($C42)-SQRT($D42)*F$40)/SQRT(1-$D42))<0.03%, 0.03%, NORMSDIST((NORMSINV($C42)-SQRT($D42)*F$40)/SQRT(1-$D42)) ), 0.03% ) -> 0.0003 | G42: =IFERROR( IF( NORMSDIST((NORMSINV($C42)-SQRT($D42)*G$40)/SQRT(1-$D42))<0.03%, 0.03%, NORMSDIST((NORMSINV($C42)-SQRT($D42)*G$40)/SQRT(1-$D42)) ), 0.03% ) -> 0.0003 | H42: =IFERROR( IF( NORMSDIST((NORMSINV($C42)-SQRT($D42)*H$40)/SQRT(1-$D42))<0.03%, 0.03%, NORMSDIST((NORMSINV($C42)-SQRT($D42)*H$40)/SQRT(1-$D42)) ), 0.03% ) -> 0.0003 | I42: =IFERROR( IF( NORMSDIST((NORMSINV($C42)-SQRT($D42)*I$40)/SQRT(1-$D42))<0.03%, 0.03%, NORMSDIST((NORMSINV($C42)-SQRT($D42)*I$40)/SQRT(1-$D42)) ), 0.03% ) -> 0.0003 | J42: =IFERROR( IF( NORMSDIST((NORMSINV($C42)-SQRT($D42)*J$40)/SQRT(1-$D42))<0.03%, 0.03%, NORMSDIST((NORMSINV($C42)-SQRT($D42)*J$40)/SQRT(1-$D42)) ), 0.03% ) -> 0.0003
B43: =B27 -> AA | C43: =C12 -> 0.0029 | D43: =(0.12*(1-EXP(-50*C43))/(1-EXP(-50)))+0.24*(1-(1-EXP(-50*C43))/(1-EXP(-50))) -> 0.22380268 | E43: =IFERROR( IF( NORMSDIST((NORMSINV($C43)-SQRT($D43)*E$40)/SQRT(1-$D43))<0.03%, 0.03%, NORMSDIST((NORMSINV($C43)-SQRT($D43)*E$40)/SQRT(1-$D43)) ), 0.03% ) -> 0.0003 | F43: =IFERROR( IF( NORMSDIST((NORMSINV($C43)-SQRT($D43)*F$40)/SQRT(1-$D43))<0.03%, 0.03%, NORMSDIST((NORMSINV($C43)-SQRT($D43)*F$40)/SQRT(1-$D43)) ), 0.03% ) -> 0.0003 | G43: =IFERROR( IF( NORMSDIST((NORMSINV($C43)-SQRT($D43)*G$40)/SQRT(1-$D43))<0.03%, 0.03%, NORMSDIST((NORMSINV($C43)-SQRT($D43)*G$40)/SQRT(1-$D43)) ), 0.03% ) -> 0.0003 | H43: =IFERROR( IF( NORMSDIST((NORMSINV($C43)-SQRT($D43)*H$40)/SQRT(1-$D43))<0.03%, 0.03%, NORMSDIST((NORMSINV($C43)-SQRT($D43)*H$40)/SQRT(1-$D43)) ), 0.03% ) -> 0.0003 | I43: =IFERROR( IF( NORMSDIST((NORMSINV($C43)-SQRT($D43)*I$40)/SQRT(1-$D43))<0.03%, 0.03%, NORMSDIST((NORMSINV($C43)-SQRT($D43)*I$40)/SQRT(1-$D43)) ), 0.03% ) -> 0.0003 | J43: =IFERROR( IF( NORMSDIST((NORMSINV($C43)-SQRT($D43)*J$40)/SQRT(1-$D43))<0.03%, 0.03%, NORMSDIST((NORMSINV($C43)-SQRT($D43)*J$40)/SQRT(1-$D43)) ), 0.03% ) -> 0.0003
B44: =B28 -> AA- | C44: =C13 -> 0.0029 | D44: =(0.12*(1-EXP(-50*C44))/(1-EXP(-50)))+0.24*(1-(1-EXP(-50*C44))/(1-EXP(-50))) -> 0.22380268 | E44: =IFERROR( IF( NORMSDIST((NORMSINV($C44)-SQRT($D44)*E$40)/SQRT(1-$D44))<0.03%, 0.03%, NORMSDIST((NORMSINV($C44)-SQRT($D44)*E$40)/SQRT(1-$D44)) ), 0.03% ) -> 0.0003 | F44: =IFERROR( IF( NORMSDIST((NORMSINV($C44)-SQRT($D44)*F$40)/SQRT(1-$D44))<0.03%, 0.03%, NORMSDIST((NORMSINV($C44)-SQRT($D44)*F$40)/SQRT(1-$D44)) ), 0.03% ) -> 0.0003 | G44: =IFERROR( IF( NORMSDIST((NORMSINV($C44)-SQRT($D44)*G$40)/SQRT(1-$D44))<0.03%, 0.03%, NORMSDIST((NORMSINV($C44)-SQRT($D44)*G$40)/SQRT(1-$D44)) ), 0.03% ) -> 0.0003 | H44: =IFERROR( IF( NORMSDIST((NORMSINV($C44)-SQRT($D44)*H$40)/SQRT(1-$D44))<0.03%, 0.03%, NORMSDIST((NORMSINV($C44)-SQRT($D44)*H$40)/SQRT(1-$D44)) ), 0.03% ) -> 0.0003 | I44: =IFERROR( IF( NORMSDIST((NORMSINV($C44)-SQRT($D44)*I$40)/SQRT(1-$D44))<0.03%, 0.03%, NORMSDIST((NORMSINV($C44)-SQRT($D44)*I$40)/SQRT(1-$D44)) ), 0.03% ) -> 0.0003 | J44: =IFERROR( IF( NORMSDIST((NORMSINV($C44)-SQRT($D44)*J$40)/SQRT(1-$D44))<0.03%, 0.03%, NORMSDIST((NORMSINV($C44)-SQRT($D44)*J$40)/SQRT(1-$D44)) ), 0.03% ) -> 0.0003
B45: =B29 -> A+ | C45: =C14 -> 0.0066 | D45: =(0.12*(1-EXP(-50*C45))/(1-EXP(-50)))+0.24*(1-(1-EXP(-50*C45))/(1-EXP(-50))) -> 0.20627085 | E45: =IFERROR( IF( NORMSDIST((NORMSINV($C45)-SQRT($D45)*E$40)/SQRT(1-$D45))<0.03%, 0.03%, NORMSDIST((NORMSINV($C45)-SQRT($D45)*E$40)/SQRT(1-$D45)) ), 0.03% ) -> 0.00079589045 | F45: =IFERROR( IF( NORMSDIST((NORMSINV($C45)-SQRT($D45)*F$40)/SQRT(1-$D45))<0.03%, 0.03%, NORMSDIST((NORMSINV($C45)-SQRT($D45)*F$40)/SQRT(1-$D45)) ), 0.03% ) -> 0.00046775427 | G45: =IFERROR( IF( NORMSDIST((NORMSINV($C45)-SQRT($D45)*G$40)/SQRT(1-$D45))<0.03%, 0.03%, NORMSDIST((NORMSINV($C45)-SQRT($D45)*G$40)/SQRT(1-$D45)) ), 0.03% ) -> 0.0003 | H45: =IFERROR( IF( NORMSDIST((NORMSINV($C45)-SQRT($D45)*H$40)/SQRT(1-$D45))<0.03%, 0.03%, NORMSDIST((NORMSINV($C45)-SQRT($D45)*H$40)/SQRT(1-$D45)) ), 0.03% ) -> 0.0003 | I45: =IFERROR( IF( NORMSDIST((NORMSINV($C45)-SQRT($D45)*I$40)/SQRT(1-$D45))<0.03%, 0.03%, NORMSDIST((NORMSINV($C45)-SQRT($D45)*I$40)/SQRT(1-$D45)) ), 0.03% ) -> 0.0003 | J45: =IFERROR( IF( NORMSDIST((NORMSINV($C45)-SQRT($D45)*J$40)/SQRT(1-$D45))<0.03%, 0.03%, NORMSDIST((NORMSINV($C45)-SQRT($D45)*J$40)/SQRT(1-$D45)) ), 0.03% ) -> 0.0003
B46: =B30 -> A | C46: =C15 -> 0.0066 | D46: =(0.12*(1-EXP(-50*C46))/(1-EXP(-50)))+0.24*(1-(1-EXP(-50*C46))/(1-EXP(-50))) -> 0.20627085 | E46: =IFERROR( IF( NORMSDIST((NORMSINV($C46)-SQRT($D46)*E$40)/SQRT(1-$D46))<0.03%, 0.03%, NORMSDIST((NORMSINV($C46)-SQRT($D46)*E$40)/SQRT(1-$D46)) ), 0.03% ) -> 0.00079589045 | F46: =IFERROR( IF( NORMSDIST((NORMSINV($C46)-SQRT($D46)*F$40)/SQRT(1-$D46))<0.03%, 0.03%, NORMSDIST((NORMSINV($C46)-SQRT($D46)*F$40)/SQRT(1-$D46)) ), 0.03% ) -> 0.00046775427 | G46: =IFERROR( IF( NORMSDIST((NORMSINV($C46)-SQRT($D46)*G$40)/SQRT(1-$D46))<0.03%, 0.03%, NORMSDIST((NORMSINV($C46)-SQRT($D46)*G$40)/SQRT(1-$D46)) ), 0.03% ) -> 0.0003 | H46: =IFERROR( IF( NORMSDIST((NORMSINV($C46)-SQRT($D46)*H$40)/SQRT(1-$D46))<0.03%, 0.03%, NORMSDIST((NORMSINV($C46)-SQRT($D46)*H$40)/SQRT(1-$D46)) ), 0.03% ) -> 0.0003 | I46: =IFERROR( IF( NORMSDIST((NORMSINV($C46)-SQRT($D46)*I$40)/SQRT(1-$D46))<0.03%, 0.03%, NORMSDIST((NORMSINV($C46)-SQRT($D46)*I$40)/SQRT(1-$D46)) ), 0.03% ) -> 0.0003 | J46: =IFERROR( IF( NORMSDIST((NORMSINV($C46)-SQRT($D46)*J$40)/SQRT(1-$D46))<0.03%, 0.03%, NORMSDIST((NORMSINV($C46)-SQRT($D46)*J$40)/SQRT(1-$D46)) ), 0.03% ) -> 0.0003
B47: =B31 -> A- | C47: =C16 -> 0.0066 | D47: =(0.12*(1-EXP(-50*C47))/(1-EXP(-50)))+0.24*(1-(1-EXP(-50*C47))/(1-EXP(-50))) -> 0.20627085 | E47: =IFERROR( IF( NORMSDIST((NORMSINV($C47)-SQRT($D47)*E$40)/SQRT(1-$D47))<0.03%, 0.03%, NORMSDIST((NORMSINV($C47)-SQRT($D47)*E$40)/SQRT(1-$D47)) ), 0.03% ) -> 0.00079589045 | F47: =IFERROR( IF( NORMSDIST((NORMSINV($C47)-SQRT($D47)*F$40)/SQRT(1-$D47))<0.03%, 0.03%, NORMSDIST((NORMSINV($C47)-SQRT($D47)*F$40)/SQRT(1-$D47)) ), 0.03% ) -> 0.00046775427 | G47: =IFERROR( IF( NORMSDIST((NORMSINV($C47)-SQRT($D47)*G$40)/SQRT(1-$D47))<0.03%, 0.03%, NORMSDIST((NORMSINV($C47)-SQRT($D47)*G$40)/SQRT(1-$D47)) ), 0.03% ) -> 0.0003 | H47: =IFERROR( IF( NORMSDIST((NORMSINV($C47)-SQRT($D47)*H$40)/SQRT(1-$D47))<0.03%, 0.03%, NORMSDIST((NORMSINV($C47)-SQRT($D47)*H$40)/SQRT(1-$D47)) ), 0.03% ) -> 0.0003 | I47: =IFERROR( IF( NORMSDIST((NORMSINV($C47)-SQRT($D47)*I$40)/SQRT(1-$D47))<0.03%, 0.03%, NORMSDIST((NORMSINV($C47)-SQRT($D47)*I$40)/SQRT(1-$D47)) ), 0.03% ) -> 0.0003 | J47: =IFERROR( IF( NORMSDIST((NORMSINV($C47)-SQRT($D47)*J$40)/SQRT(1-$D47))<0.03%, 0.03%, NORMSDIST((NORMSINV($C47)-SQRT($D47)*J$40)/SQRT(1-$D47)) ), 0.03% ) -> 0.0003
B48: =B32 -> BBB+ | C48: =C17 -> 0.0221 | D48: =(0.12*(1-EXP(-50*C48))/(1-EXP(-50)))+0.24*(1-(1-EXP(-50*C48))/(1-EXP(-50))) -> 0.15974531 | E48: =IFERROR( IF( NORMSDIST((NORMSINV($C48)-SQRT($D48)*E$40)/SQRT(1-$D48))<0.03%, 0.03%, NORMSDIST((NORMSINV($C48)-SQRT($D48)*E$40)/SQRT(1-$D48)) ), 0.03% ) -> 0.0059275591 | F48: =IFERROR( IF( NORMSDIST((NORMSINV($C48)-SQRT($D48)*F$40)/SQRT(1-$D48))<0.03%, 0.03%, NORMSDIST((NORMSINV($C48)-SQRT($D48)*F$40)/SQRT(1-$D48)) ), 0.03% ) -> 0.0040690229 | G48: =IFERROR( IF( NORMSDIST((NORMSINV($C48)-SQRT($D48)*G$40)/SQRT(1-$D48))<0.03%, 0.03%, NORMSDIST((NORMSINV($C48)-SQRT($D48)*G$40)/SQRT(1-$D48)) ), 0.03% ) -> 0.0026602318 | H48: =IFERROR( IF( NORMSDIST((NORMSINV($C48)-SQRT($D48)*H$40)/SQRT(1-$D48))<0.03%, 0.03%, NORMSDIST((NORMSINV($C48)-SQRT($D48)*H$40)/SQRT(1-$D48)) ), 0.03% ) -> 0.0016082894 | I48: =IFERROR( IF( NORMSDIST((NORMSINV($C48)-SQRT($D48)*I$40)/SQRT(1-$D48))<0.03%, 0.03%, NORMSDIST((NORMSINV($C48)-SQRT($D48)*I$40)/SQRT(1-$D48)) ), 0.03% ) -> 0.00089825047 | J48: =IFERROR( IF( NORMSDIST((NORMSINV($C48)-SQRT($D48)*J$40)/SQRT(1-$D48))<0.03%, 0.03%, NORMSDIST((NORMSINV($C48)-SQRT($D48)*J$40)/SQRT(1-$D48)) ), 0.03% ) -> 0.00045119812
B49: =B33 -> BBB | C49: =C18 -> 0.0221 | D49: =(0.12*(1-EXP(-50*C49))/(1-EXP(-50)))+0.24*(1-(1-EXP(-50*C49))/(1-EXP(-50))) -> 0.15974531 | E49: =IFERROR( IF( NORMSDIST((NORMSINV($C49)-SQRT($D49)*E$40)/SQRT(1-$D49))<0.03%, 0.03%, NORMSDIST((NORMSINV($C49)-SQRT($D49)*E$40)/SQRT(1-$D49)) ), 0.03% ) -> 0.0059275591 | F49: =IFERROR( IF( NORMSDIST((NORMSINV($C49)-SQRT($D49)*F$40)/SQRT(1-$D49))<0.03%, 0.03%, NORMSDIST((NORMSINV($C49)-SQRT($D49)*F$40)/SQRT(1-$D49)) ), 0.03% ) -> 0.0040690229 | G49: =IFERROR( IF( NORMSDIST((NORMSINV($C49)-SQRT($D49)*G$40)/SQRT(1-$D49))<0.03%, 0.03%, NORMSDIST((NORMSINV($C49)-SQRT($D49)*G$40)/SQRT(1-$D49)) ), 0.03% ) -> 0.0026602318 | H49: =IFERROR( IF( NORMSDIST((NORMSINV($C49)-SQRT($D49)*H$40)/SQRT(1-$D49))<0.03%, 0.03%, NORMSDIST((NORMSINV($C49)-SQRT($D49)*H$40)/SQRT(1-$D49)) ), 0.03% ) -> 0.0016082894 | I49: =IFERROR( IF( NORMSDIST((NORMSINV($C49)-SQRT($D49)*I$40)/SQRT(1-$D49))<0.03%, 0.03%, NORMSDIST((NORMSINV($C49)-SQRT($D49)*I$40)/SQRT(1-$D49)) ), 0.03% ) -> 0.00089825047 | J49: =IFERROR( IF( NORMSDIST((NORMSINV($C49)-SQRT($D49)*J$40)/SQRT(1-$D49))<0.03%, 0.03%, NORMSDIST((NORMSINV($C49)-SQRT($D49)*J$40)/SQRT(1-$D49)) ), 0.03% ) -> 0.00045119812
...

Sheet Survival Analysis
B6: Survival Analysis
B8: Base | K8: Upturn | T8: Downturn
B9: Grades | C9: TTC | D9: 2026 | E9: =D9+1 -> 2027 | F9: =E9+1 -> 2028 | G9: =F9+1 -> 2029 | H9: =G9+1 -> 2030 | I9: =H9+1 -> 2031 | K9: Grades | L9: TTC | M9: 2026 | N9: =M9+1 -> 2027 | O9: =N9+1 -> 2028 | P9: =O9+1 -> 2029 | Q9: =P9+1 -> 2030 | R9: =Q9+1 -> 2031 | T9: Grades | U9: TTC | V9: 2026 | W9: =V9+1 -> 2027 | X9: =W9+1 -> 2028 | Y9: =X9+1 -> 2029 | Z9: =Y9+1 -> 2030 | AA9: =Z9+1 -> 2031
B10: =Vasicek!B10 -> AAA | C10: =Vasicek!C10 -> 0.0003 | D10: =Vasicek!E10 -> 0.0003 | E10: =Vasicek!F10 -> 0.0003 | F10: =Vasicek!G10 -> 0.0003 | G10: =Vasicek!H10 -> 0.0003 | H10: =Vasicek!I10 -> 0.0003 | I10: =Vasicek!J10 -> 0.0003 | K10: =B10 -> AAA | L10: =C10 -> 0.0003 | M10: =Vasicek!E25 -> 0.0003 | N10: =Vasicek!F25 -> 0.0003 | O10: =Vasicek!G25 -> 0.0003 | P10: =Vasicek!H25 -> 0.0003 | Q10: =Vasicek!I25 -> 0.0003 | R10: =Vasicek!J25 -> 0.0003 | T10: =K10 -> AAA | U10: =L10 -> 0.0003 | V10: =Vasicek!E41 -> 0.0003 | W10: =Vasicek!F41 -> 0.0003 | X10: =Vasicek!G41 -> 0.0003 | Y10: =Vasicek!H41 -> 0.0003 | Z10: =Vasicek!I41 -> 0.0003 | AA10: =Vasicek!J41 -> 0.0003
B11: =Vasicek!B11 -> AA+ | C11: =Vasicek!C11 -> 0.0029 | D11: =Vasicek!E11 -> 0.0003 | E11: =Vasicek!F11 -> 0.0003 | F11: =Vasicek!G11 -> 0.0003 | G11: =Vasicek!H11 -> 0.0003 | H11: =Vasicek!I11 -> 0.0003 | I11: =Vasicek!J11 -> 0.0003 | K11: =B11 -> AA+ | L11: =C11 -> 0.0029 | M11: =Vasicek!E26 -> 0.0003 | N11: =Vasicek!F26 -> 0.0003 | O11: =Vasicek!G26 -> 0.0003 | P11: =Vasicek!H26 -> 0.0003 | Q11: =Vasicek!I26 -> 0.0003 | R11: =Vasicek!J26 -> 0.0003 | T11: =K11 -> AA+ | U11: =L11 -> 0.0029 | V11: =Vasicek!E42 -> 0.0003 | W11: =Vasicek!F42 -> 0.0003 | X11: =Vasicek!G42 -> 0.0003 | Y11: =Vasicek!H42 -> 0.0003 | Z11: =Vasicek!I42 -> 0.0003 | AA11: =Vasicek!J42 -> 0.0003
B12: =Vasicek!B12 -> AA | C12: =Vasicek!C12 -> 0.0029 | D12: =Vasicek!E12 -> 0.0003 | E12: =Vasicek!F12 -> 0.0003 | F12: =Vasicek!G12 -> 0.0003 | G12: =Vasicek!H12 -> 0.0003 | H12: =Vasicek!I12 -> 0.0003 | I12: =Vasicek!J12 -> 0.0003 | K12: =B12 -> AA | L12: =C12 -> 0.0029 | M12: =Vasicek!E27 -> 0.0003 | N12: =Vasicek!F27 -> 0.0003 | O12: =Vasicek!G27 -> 0.0003 | P12: =Vasicek!H27 -> 0.0003 | Q12: =Vasicek!I27 -> 0.0003 | R12: =Vasicek!J27 -> 0.0003 | T12: =K12 -> AA | U12: =L12 -> 0.0029 | V12: =Vasicek!E43 -> 0.0003 | W12: =Vasicek!F43 -> 0.0003 | X12: =Vasicek!G43 -> 0.0003 | Y12: =Vasicek!H43 -> 0.0003 | Z12: =Vasicek!I43 -> 0.0003 | AA12: =Vasicek!J43 -> 0.0003
B13: =Vasicek!B13 -> AA- | C13: =Vasicek!C13 -> 0.0029 | D13: =Vasicek!E13 -> 0.0003 | E13: =Vasicek!F13 -> 0.0003 | F13: =Vasicek!G13 -> 0.0003 | G13: =Vasicek!H13 -> 0.0003 | H13: =Vasicek!I13 -> 0.0003 | I13: =Vasicek!J13 -> 0.0003 | K13: =B13 -> AA- | L13: =C13 -> 0.0029 | M13: =Vasicek!E28 -> 0.0003 | N13: =Vasicek!F28 -> 0.0003 | O13: =Vasicek!G28 -> 0.0003 | P13: =Vasicek!H28 -> 0.0003 | Q13: =Vasicek!I28 -> 0.0003 | R13: =Vasicek!J28 -> 0.0003 | T13: =K13 -> AA- | U13: =L13 -> 0.0029 | V13: =Vasicek!E44 -> 0.0003 | W13: =Vasicek!F44 -> 0.0003 | X13: =Vasicek!G44 -> 0.0003 | Y13: =Vasicek!H44 -> 0.0003 | Z13: =Vasicek!I44 -> 0.0003 | AA13: =Vasicek!J44 -> 0.0003
B14: =Vasicek!B14 -> A+ | C14: =Vasicek!C14 -> 0.0066 | D14: =Vasicek!E14 -> 0.00068917818 | E14: =Vasicek!F14 -> 0.00037879399 | F14: =Vasicek!G14 -> 0.0003 | G14: =Vasicek!H14 -> 0.0003 | H14: =Vasicek!I14 -> 0.0003 | I14: =Vasicek!J14 -> 0.0003 | K14: =B14 -> A+ | L14: =C14 -> 0.0066 | M14: =Vasicek!E29 -> 0.00059580224 | N14: =Vasicek!F29 -> 0.00030576408 | O14: =Vasicek!G29 -> 0.0003 | P14: =Vasicek!H29 -> 0.0003 | Q14: =Vasicek!I29 -> 0.0003 | R14: =Vasicek!J29 -> 0.0003 | T14: =K14 -> A+ | U14: =L14 -> 0.0066 | V14: =Vasicek!E45 -> 0.00079589045 | W14: =Vasicek!F45 -> 0.00046775427 | X14: =Vasicek!G45 -> 0.0003 | Y14: =Vasicek!H45 -> 0.0003 | Z14: =Vasicek!I45 -> 0.0003 | AA14: =Vasicek!J45 -> 0.0003
